Workbook
Name mos: '[1]Общие данные'!$C$23:$D$23
Name mulk: '[1]Общие данные'!$C$24:$W$24

Sheet malumot
A1: =CONCATENATE(B65," olish uchun ariza") -> mikroqarz olish uchun ariza | B1: №659-SR
A2: =CONCATENATE(B65," olish uchun ariza sanasi QO’L BILAN KIRITILADI") -> mikroqarz olish uchun ariza sanasi QO’L BILAN KIRITILADI | B2: 24.03.2025 | D2: =180+B2 -> 45920
A4: Qarz oluvchi bo’yicha ma’lumotlar
A5: Ariza beruvchining FISh (kim? – Ibragimov Rustam Sadikovich) | B5: SHAYMARDANOVA SABOXAT YULDASHEVNA | C5: yu
A6: agar o’zgarishlar bo’lgan bo’lsa oldingi FISh (Sadikov Rustam Sadikovich yoki yo’q) | B6: yo’q | C6: ha | D6: yo’q
A7: Ariza beruvchining FISh (kim? – Ibragimov R.S.) | B7: SHAYMARDANOVA S.Y.
A8: FISh (ariza kimdan? – Ibragimov Rustam Sadikovichdan) | B8: =B5 -> SHAYMARDANOVA SABOXAT YULDASHEVNA
A9: FISh (kimdan? – Ibragimov R.S.dan) | B9: =B7 -> SHAYMARDANOVA S.Y.
A10: FISh (kimga? – Ibragimov Rustam Sadikovichga) | B10: =B8 -> SHAYMARDANOVA SABOXAT YULDASHEVNA
A11: FISh (kimga? – Ibragimov R.S.ga) | B11: =B9 -> SHAYMARDANOVA S.Y.
A12: FISh (kim bilan? – Ibragimov Rustam Sadikovich bilan) | B12: =B10 -> SHAYMARDANOVA SABOXAT YULDASHEVNA
A13: FISh (kim bilan? – Ibragimov R.S. bilan) | B13: =B11 -> SHAYMARDANOVA S.Y.
A14: Fuqaroligi (O’zbekiston Respublikasi) | B14: O’zbekiston Respublikasi
A15: Tug’ilgan sanasi (01.10.2011 yil) | B15: 09.11.1976 yil
A16: Pasport seriyasi (СА №1234567) | B16: AC 1659096
B17: SURXONDARYO VILOYATI JARQO'RG'ON TUMANI IIB | D17: =TEXT(C17,"ДД.ММ.ГГГГ") -> 00.01.1900
B18: 43517 | C18: =TEXT(B18,"ДД.ММ.ГГГГ") -> 21.02.2019
B19: 47169 | C19: =TEXT(B19,"ДД.ММ.ГГГГ") -> 20.02.2029
A20: Kim va qachon berilgan (Toshkent shahri Chilonzor IIB tomonidan 2011 yil __.____) | B20: =""&B17&" tomonidan "&C18&" yilda berilgan" -> SURXONDARYO VILOYATI JARQO'RG'ON TUMANI IIB tomonidan 21.02.2019 yilda berilgan | C20: =""&B17&" tomonidan "&C18&" yilda berilgan" -> SURXONDARYO VILOYATI JARQO'RG'ON TUMANI IIB tomonidan 21.02.2019 yilda berilgan
A21: Pasportni amal qilish muddati (01.10.2011 yilgacha / yoki muddatsiz) | B21: =""&C19&" y." -> 20.02.2029 y. | C21: =""&C19&" yilgacha" -> 20.02.2029 yilgacha
A22: doimiy ro’yhatdan o’tgan joyi (Toshkent sh., Mirobod tumani, Nukus ko’chasi, 1 uy, 1 honadon) | B22: SURXONDAEYO VILOYATU JARQO'RG'ON TUMANI QORAYONTOQ MFY IBN SINO KO'CHASI 114-UY | C22: =TEXT(B19,"ДД.ММ.ГГГГ") -> 20.02.2029
A23: doimiy ro’yhatdan o’tgan joyi haqiqatdagi turar joyi bilan mos keladi/mos kelmaydi | B23: mos keladi | C23: mos keladi | D23: mos kelmaydi
A24: Ro’yhatdan o’tish joyida yashash asosi | B24: Mulk huquqi | C24: Mulk huquqi | D24: ijara | E24: служебная | F24: другое | G24: -
A25: Telefon raqami kod bilan ((99871) 277 77 77) | B25: 93-763-00-67 MIJOZ
A26: Mo’ljal | B26: QORAYONTOQ BEKAT
B27: =IF(B23="mos keladi",B22,B28) -> SURXONDAEYO VILOYATU JARQO'RG'ON TUMANI QORAYONTOQ MFY IBN SINO KO'CHASI 114-UY
A28: Haqiqatdagi yashash joyi (Toshkent sh., Mirobod tumani, Nukus ko’chasi, 1 uy, 1 honadon) | B28: SURXONDARYO VILOYATI JARQO'RG'ON TUMANI QORAYONTOQ MFY IBN SINO KO'CHASI 114-UY
A29: Haqiqatdagi yashash joyida turish asosi | B29: Mulk huquqi | C29: Mulk huquqi | D29: ijara | E29: xizmat | F29: boshqa | G29: -
A30: Mijozning jinsi | B30: ayol | C30: erkak | D30: ayol
A31: Tug’ilgan joyi (Toshkent) | B31: JARQO'RG'ON TUMANI | C31: i
A32: Fuqaroligi (O’zbekiston Respublikasi) | B32: O’zbekiston Respublikasi
A33: Telefon raqami kod bilan ((99871) 277 77 77) | B33: 93-761-09-76 TURMUSH O'RTOG'I
B34: =IF(B23="mos keladi",B26,B35) -> QORAYONTOQ BEKAT
A35: Mo’ljal
A36: Oilaviy ahvoli
A37: Oila a'zolari soni (jami):
A38: Ma’lumoti
A39: Mutaxassisligi | B39: {=+A39:B102} -> Mutaxassisligi
A40: Ish telefoni raqami kod bilan ((99890) 3270000) | B40: 94-706-67-09 UY RAQAMI
A41: Mobil telefon raqami kod bilan ((99890) 3270000) | B41: 93-763-00-67 MIJOZ
...

Sheet shartnoma
A1: =""&malumot!C64&" shartnoma "&malumot!B66&"" -> Mikroqarz shartnoma №659-SR
A3: ="Toshkent shahri "&malumot!B70&"" -> Toshkent shahri 24 mart 2025 y.
A5: =""&malumot!B153&", bundan buyon «Mikromoliya tashkiloti» deb nomlanuvchi, ishonchnoma asosida xarakat qiluvchi "&malumot!A156&" "&malumot!B156&" bir tomondan va o‘z manfaati yo‘lida hamda o‘z nomidan harakat qiluvchi O‘zbekiston Respublikasi fuqarosi "&malumot!B5&" (pasport raqami "&malumot!B16&", "&malumot!C20&" ), bundan buyon «Qarz oluvchi» deb nomlanuvchi, boshqa tomondan, birgalikda “Tomonlar” yoki alohida “Tomon” deb nomlanuvchilar, Qarz oluvchi tomonidan "&TEXT(malumot!B2,"ДД.ММ.ГГГГ")&" yil,"&malumot!B65&" olish uchun ariza berilganligini hisobga olib, ushbu "&malumot!C64&" shartnomasini (bundan keyin – «Shartnoma») quyidagilar haqida tuzdilar:" -> «CLEVER MIKROMOLIYA TASHKILOTI» MChJ, bundan buyon «Mikromoliya tashkiloti» deb nomlanuvchi, ishonchnoma asosida xarakat qiluvchi Surxondaryo filiali boshlig'i A.PARDAYEV bir tomondan va o‘z manfaati yo‘lida hamda o‘z nomidan harakat qiluvchi O‘zbekiston Respublikasi fuqarosi SHAYMARDANOVA SABOXAT YULDASHEVNA (pasport raqami AC 1659096, SURXONDARYO VILOYATI JARQO'RG'ON TUMANI IIB tomonidan 21.02.2019 yilda berilgan ), bundan buyon «Qarz oluvchi» deb nomlanuvchi, boshqa tomondan, birgalikda “Tomonlar” yoki alohida “Tomon” deb nomlanuvchilar, Qarz oluvchi tomonidan 24.03.2025 yil,mikroqarz olish uchun ariza berilganligini hisobga olib, ushbu Mikroqarz shartnomasini (bundan keyin – «Shartnoma») quyidagilar haqida tuzdilar:
A7: 1. SHARTNOMA PREDMETI
A8: ="1.1. Mikromoliya tashkiloti Qarz oluvchiga umumiy miqdori "&FIXED(malumot!B75,2)&" ("&malumot!C76&") bo‘lgan "&malumot!B65&"ni "&malumot!B71&" dan "&malumot!B73&" gacha bo'lgan muddatga naqd pul va/yoki o'tkazmasi shaklida ajratadi." -> 1.1. Mikromoliya tashkiloti Qarz oluvchiga umumiy miqdori 52 000 000,00 (Ellik ikki million so'm) bo‘lgan mikroqarzni 24 mart 2025 y. dan 24 mart 2028 y. gacha bo'lgan muddatga naqd pul va/yoki o'tkazmasi shaklida ajratadi.
A9: ="1.2. Qarz oluvchi to‘lovlilik, muddatlilik va ta’minlanganlik tamoyillariga amal qilgan holda "&malumot!B65&"dan foydalanish majburiyatini o‘z zimmasiga oladi." -> 1.2. Qarz oluvchi to‘lovlilik, muddatlilik va ta’minlanganlik tamoyillariga amal qilgan holda mikroqarzdan foydalanish majburiyatini o‘z zimmasiga oladi.
A11: ="2. "&malumot!D64&" BERISH VA QAYTARISH TARTIBI" -> 2. MIKROQARZ BERISH VA QAYTARISH TARTIBI
A12: ="2.1. Ushbu Shartnomaning 1.1.-bandida ko‘rsatilgan summa miqdoridagi "&malumot!B65&" Mikromoliya tashkiloti kassasidan naqd pul shaklida va/yoki plastik kartaga o‘tkazish yuli bilan beriladi." -> 2.1. Ushbu Shartnomaning 1.1.-bandida ko‘rsatilgan summa miqdoridagi mikroqarz Mikromoliya tashkiloti kassasidan naqd pul shaklida va/yoki plastik kartaga o‘tkazish yuli bilan beriladi.
A13: ="2.2. "&malumot!C64&" berish ushbu Shartnoma tuzilgan va Qarz oluvchi tomonidan ushbu shartnomaning 3-bo‘limiga muvofiq garov ta'minoti ta'minlangandan so‘ng 10 kalendar kundan kechiktirmay amalga oshiriladi." -> 2.2. Mikroqarz berish ushbu Shartnoma tuzilgan va Qarz oluvchi tomonidan ushbu shartnomaning 3-bo‘limiga muvofiq garov ta'minoti ta'minlangandan so‘ng 10 kalendar kundan kechiktirmay amalga oshiriladi.
A14: ="2.3. "&malumot!C64&" Qarz oluvchi tomonidan ushbu Shartnomaning ajralmas qismi hisoblanadigan 1-ilovasida ko‘rsatilgan to‘lov jadvalida (bundan keyin - To‘lov jadvali) belgilangan miqdor, tartib va muddatlarda qaytariladi." -> 2.3. Mikroqarz Qarz oluvchi tomonidan ushbu Shartnomaning ajralmas qismi hisoblanadigan 1-ilovasida ko‘rsatilgan to‘lov jadvalida (bundan keyin - To‘lov jadvali) belgilangan miqdor, tartib va muddatlarda qaytariladi.
A15: ="2.4. Mikromoliya tashkiloti, "&malumot!B65&" berilgan vaqtdan boshlab, "&malumot!B65&" miqdorining qoldiq summasiga "&malumot!B85&"% ("&malumot!C86&") foiz yillik va yiliga 365/366 kunlik hisobidan foizlar hisoblaydi. To'lov jadvaliga muvofiq asosiy qarz bo'yicha navbatdagi to'lov buzilgan hollarda, "&"foiz stavkasi oshiriladi va Mikromoliya tashkiloti "&malumot!B65&"ning muddati o'tgan asosiy qarz summasiga yillik "&malumot!B88&" ("&malumot!B89&") foiz miqdorida foizlar hisoblaydi." -> 2.4. Mikromoliya tashkiloti, mikroqarz berilgan vaqtdan boshlab, mikroqarz miqdorining qoldiq summasiga 60% (Oltmish) foiz yillik va yiliga 365/366 kunlik hisobidan foizlar hisoblaydi. To'lov jadvaliga muvofiq asosiy qarz bo'yicha navbatdagi to'lov buzilgan hollarda, foiz stavkasi oshiriladi va Mikromoliya tashkiloti mikroqarzning muddati o'tgan asosiy qarz summasiga yillik 100 (bir yuz) foiz miqdorida foizlar hisoblaydi.
A16: 2.4.1 Qarz oluvchining xisob raqamlaridan shartnomaning 4.1.2 bandida ko‘rsatilgan tartibda yechib olingan pul mablag‘lari yechib olinganidan so‘ng mijoz tomonidan kredit qarzdorligini so‘ndirish uchun bank kassalari orqali to‘langan pul mablag‘lari yoki mijoz tomonidan kredit qarzdorligini so‘ndirish uchun bank kassalari orqali to‘langandan so‘ng qarz oluvchining xisob raqamlaridan shartnomaning 4.1.2 bandida ko‘rsatilgan tartibda yechib olingan pul mablag‘larining bir oylik kredit to‘lovini so‘ndirishga yo‘naltirilgan miqdoridan ortiqcha qismi qarz oluvchining to‘lov amalga oshirilgan kundan boshlab 3 bank ish kuni ichida yo‘llagan arizasiga asosan qarz oluvchiga qaytarilishi mumkun. 2.5. Foizlar To‘lov jadvaliga muvofiq asosiy qarzni qaytarish uchun belgilangan sanada to‘lanadi. 2.5.1 Qarz oluvchi tomonidan shartnomaning 2.4 bandida ko‘rsatilgan muddatda ortiqcha to‘langan pul mablag‘larini qaytarish to‘g‘risida ariza berilmagan taqdirda to‘langan ortiqcha pul mablag‘lari mijozning asosiy qarzdorligini so‘ndirishga yo‘naltiriladi.
A17: =CONCATENATE(C17,H17,I17) -> 2.6 Qarz oluvchi tomonidan to‘lov jadvalida ko‘rsatilgan muddatdan oldin xamda to‘lov jadvalida ko‘rsatilgan oylik kredit qarzdorligini so‘ndirish miqdoridan ko‘p miqdorda to‘lovni amalga oshirib, to‘langan pul mablag‘larini asosiy kredit qarzdorligini so‘ndirishga yo‘naltirilishini so‘ralganda qarz oluvchining kredit qarzdorligini so‘ndirish uchun to‘lagan pul mablag‘laridan kredit qarzdorligi to‘langan oy uchun to‘lov jadvali bo‘yicha so‘ndirilishi lozim bo‘lgan foiz qarzdorligi summasi, to‘lov jadvalida foiz qarzdorligi so‘ndirilishi ko‘rsatilgan muddatga qadar tashkilotning xisob raqamida saqlanib to‘lov jadvalida ko‘rsatilgan sanada oylik foiz qarzdorligini so‘ndirishga yo‘naltiriladi. 2.6.1. Qarz oluvchi tomonidan olingan mikroqarzni va undan foydalanganlik uchun foizlarni qaytarish bo‘yicha muddati o‘tgan qarzdorlik hosil bo‘lganda Qarz oluvchi tomonidan ko‘rsatilgan qarzdorlikni to‘lash hisobiga to‘lanadigan summalar quyidagi tartibda hisobga olinadi: | C17: 2.6 Qarz oluvchi tomonidan to‘lov jadvalida ko‘rsatilgan muddatdan oldin xamda to‘lov jadvalida ko‘rsatilgan oylik kredit qarzdorligini so‘ndirish miqdoridan ko‘p miqdorda to‘lovni amalga oshirib, to‘langan pul mablag‘larini asosiy kredit qarzdorligini so‘ndirishga yo‘naltirilishini so‘ralganda qarz oluvchining kredit qarzdorligini so‘ndirish uchun to‘lagan pul mablag‘laridan kredit qarzdorligi to‘langan oy uchun to‘lov jadvali bo‘yicha so‘ndirilishi lozim bo‘lgan foiz qarzdorligi summasi, to‘lov jadvalida foiz qarzdorligi so‘ndirilishi ko‘rsatilgan muddatga qadar tashkilotning xisob raqamida saqlanib to‘lov jadvalida ko‘rsatilgan sanada oylik foiz qarzdorligini so‘ndirishga yo‘naltiriladi. 2.6.1. Qarz oluvchi tomonidan olingan | H17: =malumot!B65 -> mikroqarz | I17: ni va undan foydalanganlik uchun foizlarni qaytarish bo‘yicha muddati o‘tgan qarzdorlik hosil bo‘lganda Qarz oluvchi tomonidan ko‘rsatilgan qarzdorlikni to‘lash hisobiga to‘lanadigan summalar quyidagi tartibda hisobga olinadi:
A18: - jarima sanksiyalarni to‘lash; - to‘lov muddati o‘tgan foizlarni to‘lash; - to‘lov muddati o‘tgan asosiy qarzni to‘lash; - muddatli qarz bo‘yicha hisoblangan foizlarni to‘lash; - muddatli asosiy qarzni to‘lash; - Mikromoliya tashkilotning boshqa zararlarini qoplash.
A19: ="2.7. Qarz oluvchi Mikromoliya tashkilotining "&malumot!B65&" bo‘yicha asosiy summasi, hisoblangan foizlarni, penya va boshqa moliyaviy talablarini ham naqd pul shaklida, ham naqdsiz shaklda qaytarib beradi." -> 2.7. Qarz oluvchi Mikromoliya tashkilotining mikroqarz bo‘yicha asosiy summasi, hisoblangan foizlarni, penya va boshqa moliyaviy talablarini ham naqd pul shaklida, ham naqdsiz shaklda qaytarib beradi.
A20: ="2.8. Qarz oluvchi "&malumot!B65&" miqdorini muddatidan oldin qaytarish, shuningdek, bu haqida Mikromoliya tashkilotini albatta ogohlantirgan holda ulardan aniq foydalangan muddat uchun hisoblangan foizlarni to‘lash huquqiga ega." -> 2.8. Qarz oluvchi mikroqarz miqdorini muddatidan oldin qaytarish, shuningdek, bu haqida Mikromoliya tashkilotini albatta ogohlantirgan holda ulardan aniq foydalangan muddat uchun hisoblangan foizlarni to‘lash huquqiga ega.
A21: =CONCATENATE(C21,H21,I21) -> 2.9. Qarz oluvchi jismoniy shaxslarning kreditlar (mikroqarzlar) bo‘yicha qarz yukini hisoblash tartibi, qarz yukining ruxsat etilgan miqdori, shuningdek qarz yuki o‘sishini cheklash to‘g‘risidagi Nizomga muvofiq (O’zbekiston Respublikasi Adliya vazirligi tomonidan 19.12.2019 y. 3205-son bilan ro‘yxatga olingan Markaziy bank Boshqaruvining 28.09.2019 y. 24/5-son qarori bilan tasdiqlangan), qarz yuki ko‘rsatkichi har bir qarz oluvchiga qarz beruvchi tomonidan mikroqarz ajratishda uning summasi va qarz oluvchining amaldagi kredit (mikroqarz) shartnomalari bo‘yicha asosiy qarz qoldig‘i yig‘indisi bazaviy hisoblash miqdorining 50 baravaridan oshganda hisoblanadi. | C21: ="2.9. Qarz oluvchi jismoniy shaxslarning kreditlar ("&malumot!B65&"lar) bo‘yicha qarz yukini hisoblash tartibi, qarz yukining ruxsat etilgan miqdori, shuningdek qarz yuki o‘sishini cheklash to‘g‘risidagi Nizomga muvofiq (O’zbekiston Respublikasi Adliya vazirligi tomonidan 19.12.2019 y. 3205-son bilan ro‘yxatga " -> 2.9. Qarz oluvchi jismoniy shaxslarning kreditlar (mikroqarzlar) bo‘yicha qarz yukini hisoblash tartibi, qarz yukining ruxsat etilgan miqdori, shuningdek qarz yuki o‘sishini cheklash to‘g‘risidagi Nizomga muvofiq (O’zbekiston Respublikasi Adliya vazirligi tomonidan 19.12.2019 y. 3205-son bilan ro‘yxatga | H21: ="olingan Markaziy bank Boshqaruvining 28.09.2019 y. 24/5-son qarori bilan tasdiqlangan), qarz yuki ko‘rsatkichi har bir qarz oluvchiga qarz beruvchi tomonidan "&malumot!B65&" ajratishda uning summasi va " -> olingan Markaziy bank Boshqaruvining 28.09.2019 y. 24/5-son qarori bilan tasdiqlangan), qarz yuki ko‘rsatkichi har bir qarz oluvchiga qarz beruvchi tomonidan mikroqarz ajratishda uning summasi va | I21: ="qarz oluvchining amaldagi kredit ("&malumot!B65&") shartnomalari bo‘yicha asosiy qarz qoldig‘i yig‘indisi bazaviy hisoblash miqdorining 50 baravaridan oshganda hisoblanadi." -> qarz oluvchining amaldagi kredit (mikroqarz) shartnomalari bo‘yicha asosiy qarz qoldig‘i yig‘indisi bazaviy hisoblash miqdorining 50 baravaridan oshganda hisoblanadi.
A22: ="3. "&malumot!D64&" TA'MINOTI BO‘YICHA " -> 3. MIKROQARZ TA'MINOTI BO‘YICHA
A23: ="3.1. Ushbu Shartnoma bo‘yicha taqdim etilgan "&malumot!C64&" quyidagi garov bilan ta'minlanadi:" -> 3.1. Ushbu Shartnoma bo‘yicha taqdim etilgan Mikroqarz quyidagi garov bilan ta'minlanadi:
A24: =IF(malumot!B109=malumot!C109,shartnoma!A28,IF(malumot!B109=malumot!D109,shartnoma!A25,0)) -> 3.1.1. Mikromoliya tashkiloti, Qarz oluvchi va XUDOYKULOV ALMURAT KURBONAZAROVICH tomonidan 2025 yil 24 martda imzolangan 1-sonli garov predmeti qiymatini tasdiqlash dalolatnomasiga muvofiq SARIQ JELTO- ORANJEVIY rangli, ishlab chiqarilgan yili – 2019 yil, dvigatel raqami 3977458, shassi - RAKAMSIZ, kuzov turi - YENGIL SEDAN, kuzov raqami №XTAGFL110KY258232, davlat raqam belgisi 75M497WA bo'lgan LADA VESTA rusumli avtomashinasi (bundan keyin “Garov predmeti”), egalik huquqiga ega XUDOYKULOV ALMURAT KURBONAZAROVICHga tegishli va kelishilgan garov qiymati 2025 yil 24 martda imzolangan 1-sonli Garov predmeti qiymatini tasdiqlash dalolatnomasiga muvifiq 78 000 000,00 (yetmish sakkiz million so'm) so'mni tashkil qiladi. Garov garovining aniq shartlari tegishli notarial rasmiylashtirilgan garov shartnomasi bilan belgilanadi.
A25: =IF(malumot!B98=malumot!C98,shartnoma!A27,IF(malumot!B98=malumot!D98,shartnoma!A26,0)) -> 3.1.1. Mikromoliya tashkiloti, Qarz oluvchi va XUDOYKULOV ALMURAT KURBONAZAROVICH tomonidan 2025 yil 24 martda imzolangan 1-sonli Garov predmeti qiymatini tasdiqlash dalolatnomasiga muvofiq SAMARQAND VILOYATI TAYLOQ TUMANI CHAROG'BON MFY YANGI TAYLOQ QISHLOG'I 6 TURAR JOY 12 QAVAT 58 XONADON manzilida joylashgan, yer uchastkasi maydoni - , umumiy maydoni - 72,13, yashash maydoni - 37,39 bo'lgan, 3 - xonali yakka tartibdagi uy-joy ko'rinishidagi ko'chmas mulk (bundan keyin “Garov predmeti”), egalik huquqiga ko'ra 0ga tegishli va kelishilgan garov qiymati 2025 yil 24 martda imzolangan 1-sonli Garov predmeti qiymatini tasdiqlash dalolatnomasiga muvofiq 78 000 000,00 (yetmish sakkiz million so'm) so'mni tashkil qiladi. Garovning aniq shartlari tegishli tarzda notarial tasdiqlangan garov shartnomasi bilan belgilangan.
A26: ="3.1.1. "&malumot!N132&" tomonidan "&malumot!B149&" yil "&malumot!B151&" "&malumot!B150&"da imzolangan 1-sonli navbatdagi garov predmeti qiymatini tasdiqlash dalolatnomasiga muvofiq "&malumot!C129&" manzilida joylashgan, "&malumot!E132&" bo'lgan, "&malumot!E131&" ko'rinishidagi ko'chmas mulk (bundan keyin “navbatdagi garov predmeti”), egalik huquqiga ko'ra "&malumot!C123&"ga tegishli va kelishilgan garov qiymati "&malumot!B149&" yil "&malumot!B151&" "&malumot!B150&"da imzolangan 1-sonli Garov predmeti qiymatini tasdiqlash dalolatnomasiga muvofiq "&FIXED(malumot!B142,2)&" ("&malumot!B144&") so'mni tashkil qiladi. Garovning aniq shartlari tegishli tarzda notarial tasdiqlangan garov shartnomasi bilan belgilangan." -> 3.1.1. Mikromoliya tashkiloti, Qarz oluvchi va XUDOYKULOV ALMURAT KURBONAZAROVICH tomonidan 2025 yil 24 martda imzolangan 1-sonli navbatdagi garov predmeti qiymatini tasdiqlash dalolatnomasiga muvofiq SAMARQAND VILOYATI TAYLOQ TUMANI CHAROG'BON MFY YANGI TAYLOQ QISHLOG'I 6 TURAR JOY 12 QAVAT 58 XONADON manzilida joylashgan, yer uchastkasi maydoni - , umumiy maydoni - 72,13, yashash maydoni - 37,39 bo'lgan, 3 - xonali yakka tartibdagi uy-joy ko'rinishidagi ko'chmas mulk (bundan keyin “navbatdagi garov predmeti”), egalik huquqiga ko'ra 0ga tegishli va kelishilgan garov qiymati 2025 yil 24 martda imzolangan 1-sonli Garov predmeti qiymatini tasdiqlash dalolatnomasiga muvofiq 78 000 000,00 (yetmish sakkiz million so'm) so'mni tashkil qiladi. Garovning aniq shartlari tegishli tarzda notarial tasdiqlangan garov shartnomasi bilan belgilangan.
A27: ="3.1.1. "&malumot!N132&" tomonidan "&malumot!B149&" yil "&malumot!B151&" "&malumot!B150&"da imzolangan 1-sonli Garov predmeti qiymatini tasdiqlash dalolatnomasiga muvofiq "&malumot!C129&" manzilida joylashgan, "&malumot!E132&" bo'lgan, "&malumot!E131&" ko'rinishidagi ko'chmas mulk (bundan keyin “Garov predmeti”), egalik huquqiga ko'ra "&malumot!C123&"ga tegishli va kelishilgan garov qiymati "&malumot!B149&" yil "&malumot!B151&" "&malumot!B150&"da imzolangan 1-sonli Garov predmeti qiymatini tasdiqlash dalolatnomasiga muvofiq "&FIXED(malumot!B142,2)&" ("&malumot!B144&") so'mni tashkil qiladi. Garovning aniq shartlari tegishli tarzda notarial tasdiqlangan garov shartnomasi bilan belgilangan." -> 3.1.1. Mikromoliya tashkiloti, Qarz oluvchi va XUDOYKULOV ALMURAT KURBONAZAROVICH tomonidan 2025 yil 24 martda imzolangan 1-sonli Garov predmeti qiymatini tasdiqlash dalolatnomasiga muvofiq SAMARQAND VILOYATI TAYLOQ TUMANI CHAROG'BON MFY YANGI TAYLOQ QISHLOG'I 6 TURAR JOY 12 QAVAT 58 XONADON manzilida joylashgan, yer uchastkasi maydoni - , umumiy maydoni - 72,13, yashash maydoni - 37,39 bo'lgan, 3 - xonali yakka tartibdagi uy-joy ko'rinishidagi ko'chmas mulk (bundan keyin “Garov predmeti”), egalik huquqiga ko'ra 0ga tegishli va kelishilgan garov qiymati 2025 yil 24 martda imzolangan 1-sonli Garov predmeti qiymatini tasdiqlash dalolatnomasiga muvofiq 78 000 000,00 (yetmish sakkiz million so'm) so'mni tashkil qiladi. Garovning aniq shartlari tegishli tarzda notarial tasdiqlangan garov shartnomasi bilan belgilangan.
A28: =IF(malumot!B98=malumot!C98,A29,IF(malumot!B98=malumot!D98,A30,0)) -> 3.1.1. Mikromoliya tashkiloti, Qarz oluvchi va XUDOYKULOV ALMURAT KURBONAZAROVICH tomonidan 2025 yil 24 martda imzolangan 1-sonli garov predmeti qiymatini tasdiqlash dalolatnomasiga muvofiq SARIQ JELTO- ORANJEVIY rangli, ishlab chiqarilgan yili – 2019 yil, dvigatel raqami 3977458, shassi - RAKAMSIZ, kuzov turi - YENGIL SEDAN, kuzov raqami №XTAGFL110KY258232, davlat raqam belgisi 75M497WA bo'lgan LADA VESTA rusumli avtomashinasi (bundan keyin “Garov predmeti”), egalik huquqiga ega XUDOYKULOV ALMURAT KURBONAZAROVICHga tegishli va kelishilgan garov qiymati 2025 yil 24 martda imzolangan 1-sonli Garov predmeti qiymatini tasdiqlash dalolatnomasiga muvifiq 78 000 000,00 (yetmish sakkiz million so'm) so'mni tashkil qiladi. Garov garovining aniq shartlari tegishli notarial rasmiylashtirilgan garov shartnomasi bilan belgilanadi.
A29: ="3.1.1. "&malumot!N132&" tomonidan "&malumot!B149&" yil "&malumot!B151&" "&malumot!B150&"da imzolangan 1-sonli garov predmeti qiymatini tasdiqlash dalolatnomasiga muvofiq "&malumot!B140&" rangli, ishlab chiqarilgan yili – "&malumot!B141&" yil, dvigatel raqami "&malumot!B137&", shassi - "&malumot!B138&", kuzov turi - "&malumot!B134&", kuzov raqami №"&malumot!B135&", davlat raqam belgisi "&malumot!B132&" bo'lgan "&malumot!B131&" rusumli avtomashinasi (bundan keyin “Garov predmeti”), egalik huquqiga ega "&malumot!B123&"ga tegishli va kelishilgan garov qiymati "&malumot!B149&" yil "&malumot!B151&" "&malumot!B150&"da imzolangan 1-sonli Garov predmeti qiymatini tasdiqlash dalolatnomasiga muvifiq "&FIXED(malumot!B142,2)&" ("&malumot!B144&") so'mni tashkil qiladi. Garov garovining aniq shartlari tegishli notarial rasmiylashtirilgan garov shartnomasi bilan belgilanadi." -> 3.1.1. Mikromoliya tashkiloti, Qarz oluvchi va XUDOYKULOV ALMURAT KURBONAZAROVICH tomonidan 2025 yil 24 martda imzolangan 1-sonli garov predmeti qiymatini tasdiqlash dalolatnomasiga muvofiq SARIQ JELTO- ORANJEVIY rangli, ishlab chiqarilgan yili – 2019 yil, dvigatel raqami 3977458, shassi - RAKAMSIZ, kuzov turi - YENGIL SEDAN, kuzov raqami №XTAGFL110KY258232, davlat raqam belgisi 75M497WA bo'lgan LADA VESTA rusumli avtomashinasi (bundan keyin “Garov predmeti”), egalik huquqiga ega XUDOYKULOV ALMURAT KURBONAZAROVICHga tegishli va kelishilgan garov qiymati 2025 yil 24 martda imzolangan 1-sonli Garov predmeti qiymatini tasdiqlash dalolatnomasiga muvifiq 78 000 000,00 (yetmish sakkiz million so'm) so'mni tashkil qiladi. Garov garovining aniq shartlari tegishli notarial rasmiylashtirilgan garov shartnomasi bilan belgilanadi.
A30: ="3.1.1. "&malumot!N132&" tomonidan "&malumot!B149&" yil "&malumot!B151&" "&malumot!B150&"da imzolangan 1-sonli navbatdagi garov predmeti qiymatini tasdiqlash dalolatnomasiga muvofiq "&malumot!B140&" rangli, ishlab chiqarilgan yili – "&malumot!B141&" yil, dvigatel raqami "&malumot!B137&", shassi - "&malumot!B138&", kuzov turi - "&malumot!B134&", kuzov raqami №"&malumot!B135&", davlat raqam belgisi "&malumot!B132&" bo'lgan "&malumot!B131&" rusumli avtomashinasi (bundan keyin “navbatdagi garov predmeti”), egalik huquqiga ega "&malumot!B123&"ga tegishli va kelishilgan garov qiymati "&malumot!B149&" yil "&malumot!B151&" "&malumot!B150&"da imzolangan 1-sonli Garov predmeti qiymatini tasdiqlash dalolatnomasiga muvifiq "&FIXED(malumot!B142,2)&" ("&malumot!B144&") so'mni tashkil qiladi. Garov garovining aniq shartlari tegishli notarial rasmiylashtirilgan garov shartnomasi bilan belgilanadi." -> 3.1.1. Mikromoliya tashkiloti, Qarz oluvchi va XUDOYKULOV ALMURAT KURBONAZAROVICH tomonidan 2025 yil 24 martda imzolangan 1-sonli navbatdagi garov predmeti qiymatini tasdiqlash dalolatnomasiga muvofiq SARIQ JELTO- ORANJEVIY rangli, ishlab chiqarilgan yili – 2019 yil, dvigatel raqami 3977458, shassi - RAKAMSIZ, kuzov turi - YENGIL SEDAN, kuzov raqami №XTAGFL110KY258232, davlat raqam belgisi 75M497WA bo'lgan LADA VESTA rusumli avtomashinasi (bundan keyin “navbatdagi garov predmeti”), egalik huquqiga ega XUDOYKULOV ALMURAT KURBONAZAROVICHga tegishli va kelishilgan garov qiymati 2025 yil 24 martda imzolangan 1-sonli Garov predmeti qiymatini tasdiqlash dalolatnomasiga muvifiq 78 000 000,00 (yetmish sakkiz million so'm) so'mni tashkil qiladi. Garov garovining aniq shartlari tegishli notarial rasmiylashtirilgan garov shartnomasi bilan belgilanadi.
A31: =CONCATENATE(A32,B32) -> 3.2. Qonun hujjatlariga muvofiq rasmiylashtirilgan, “Garov predmeti” hisoblangan notarial tasdiqlangan garov shartnomasi, shu jumladan “Garov predmeti”ga taʼqiq quyilganligi tasdiqlovchi xujjat Qarz oluvchi tomonidan ushbu shartnoma tuzilgandan so‘ng 10 bank kuni mobaynida Mikromoliya tashkilotiga taqdim etilishi lozim. Garov shartnomasi belgilangan muddatda taqdim etilmagan hollarda, Mikromoliya tashkiloti Qarz oluvchining manziliga yozma bildirishnoma yuborish orqali mikroqarz berishni rad etish va / yoki ushbu shartnomani bir tomonlama bekor qilish huquqiga egadir. Bunda ushbu shartnoma Qarz oluvchi tomonidan talabnoma olingan vaqtda yoki talabnoma pochta xizmati orqali yuborilgandan keyin uchinchi kuni bekor qilingan hisoblanadi.
A32: 3.2. Qonun hujjatlariga muvofiq rasmiylashtirilgan, “Garov predmeti” hisoblangan notarial tasdiqlangan garov shartnomasi, shu jumladan “Garov predmeti”ga taʼqiq quyilganligi tasdiqlovchi xujjat Qarz oluvchi tomonidan ushbu shartnoma tuzilgandan so‘ng 10 bank kuni mobaynida | B32: =CONCATENATE(A33,B33) -> Mikromoliya tashkilotiga taqdim etilishi lozim. Garov shartnomasi belgilangan muddatda taqdim etilmagan hollarda, Mikromoliya tashkiloti Qarz oluvchining manziliga yozma bildirishnoma yuborish orqali mikroqarz berishni rad etish va / yoki ushbu shartnomani bir tomonlama bekor qilish huquqiga egadir. Bunda ushbu shartnoma Qarz oluvchi tomonidan talabnoma olingan vaqtda yoki talabnoma pochta xizmati orqali yuborilgandan keyin uchinchi kuni bekor qilingan hisoblanadi.
A33: =" Mikromoliya tashkilotiga taqdim etilishi lozim. Garov shartnomasi belgilangan muddatda taqdim etilmagan hollarda, Mikromoliya tashkiloti Qarz oluvchining manziliga yozma bildirishnoma yuborish orqali "&malumot!B65&"" -> Mikromoliya tashkilotiga taqdim etilishi lozim. Garov shartnomasi belgilangan muddatda taqdim etilmagan hollarda, Mikromoliya tashkiloti Qarz oluvchining manziliga yozma bildirishnoma yuborish orqali mikroqarz | B33: berishni rad etish va / yoki ushbu shartnomani bir tomonlama bekor qilish huquqiga egadir. Bunda ushbu shartnoma Qarz oluvchi tomonidan talabnoma olingan vaqtda yoki talabnoma pochta xizmati orqali yuborilgandan keyin uchinchi kuni bekor qilingan hisoblanadi.
A34: 3.3. Asosiy qarzni, foizlar yoki ushbu shartnoma bo‘yicha belgilangan muddatdan kechiktirilganligi bo‘yicha penyalarni qaytarish muddati kechiktirilishi yuzaga kelganda va/yoki ushbu shartnoma bo‘yicha boshqa majburiyatlar buzilishi holatlarida Mikromoliya tashkiloti O‘zbekiston Respublikasining amaldagi qonunchiligiga muvofiq qarzni undirish uchun qaytarib olinmaydigan va muqarrar tartibda unidirishni garov ob'ektiga qaratish huquqiga ega bo‘ladi.
A35: 3.4. O‘zbekiston Respublikasi "Garov to‘g‘risida" gi Qonunining 27-moddasiga muvofiq Garov predmeti sug‘urtalanmaydi. Lekin Mikromoliya tashkiloti Qarz oluvchidan Mikromoliya tashkiloti foydasiga Garov obʼektini ushbu Shartnomaning to‘liq amal qilish muddatiga har turli xavflardan sug‘urta qilishni talab qilish huquqiga ega. Bunda, sug‘urta xavflari ro‘yxati, shuningdek, sug‘urta kompaniyasi Mikromoliya tashkilotining xohishiga ko‘ra belgilanadi. Sug‘urta hodisasi yuz berganda Foyda oluvchi Mikromoliya tashkiloti bo‘lishi kerak.
A37: 4. MIKROMOLIYA TASHKILOTINING HUQUQ VA MAJBURIYATLARI
A38: 4.1. Mikromoliya tashkiloti quyidagi huquqlarga ega:
A39: =CONCATENATE(C39,H39) -> 4.1.1. Ushbu Shartnomada ko‘rsatilgan asoslar bo‘yicha Qarz oluvchiga Shartnomada ko‘zda tutilgan mikroqarz summasini berilishini to‘liq yoki qisman rad etish. 4.1.2 “Mikromoliya Tashkiloti” qarz oluvchining nomidagi barcha plastik kartalaridan, xozirgi kunda mavjud va bundan so‘ng ochiladigan barcha xisob raqamlaridan (talab qilib olguncha, depozit jamg‘arib boriladigan plastik va boshqa istalgan xisob raqamlaridan) kredit to‘lovini kredit qaytarish jadvaliga asosan oyning kredit qarzdorligi qaytarilishi ko‘rsatilgan kuni akseptsiz tarzda yechib olish xuquqiga ega.Usbu bandda belgilangan harakatlarni amalga oshirish uchun bo‘lgan barcha xarajatlar Qarz oluvchi xisobidan qoplanadi | C39: ="4.1.1. Ushbu Shartnomada ko‘rsatilgan asoslar bo‘yicha Qarz oluvchiga Shartnomada ko‘zda tutilgan "&malumot!B65&"" -> 4.1.1. Ushbu Shartnomada ko‘rsatilgan asoslar bo‘yicha Qarz oluvchiga Shartnomada ko‘zda tutilgan mikroqarz | H39: summasini berilishini to‘liq yoki qisman rad etish. 4.1.2 “Mikromoliya Tashkiloti” qarz oluvchining nomidagi barcha plastik kartalaridan, xozirgi kunda mavjud va bundan so‘ng ochiladigan barcha xisob raqamlaridan (talab qilib olguncha, depozit jamg‘arib boriladigan plastik va boshqa istalgan xisob raqamlaridan) kredit to‘lovini kredit qaytarish jadvaliga asosan oyning kredit qarzdorligi qaytarilishi ko‘rsatilgan kuni akseptsiz tarzda yechib olish xuquqiga ega.Usbu bandda belgilangan harakatlarni amalga oshirish uchun bo‘lgan barcha xarajatlar Qarz oluvchi xisobidan qoplanadi
A40: ="4.1.2.1. "&malumot!C64&" bo‘yicha qolgan barcha qarzdorlik, foiz to‘lovlarining muddatidan oldin qaytarilishini talab qilish, shuningdek, quyidagi holatlardan biri yuzaga kelganda undirishni garov ta'minotiga qaratish:" -> 4.1.2.1. Mikroqarz bo‘yicha qolgan barcha qarzdorlik, foiz to‘lovlarining muddatidan oldin qaytarilishini talab qilish, shuningdek, quyidagi holatlardan biri yuzaga kelganda undirishni garov ta'minotiga qaratish:
A41: a) ta'minotisiz qarzdorlik yuzaga kelganda;
A42: ="b) "&malumot!B65&" summasiga hisoblanadigan asosiy qarz bo‘yicha muddati o‘tgan qarzdorlik va/yoki foizlarning yuzaga kelishi;" -> b) mikroqarz summasiga hisoblanadigan asosiy qarz bo‘yicha muddati o‘tgan qarzdorlik va/yoki foizlarning yuzaga kelishi;
A43: с) Qarz oluvchini qonun hujjatlarida belgilangan tartibda to‘lov qobiliyatiga ega emas, muomalaga layoqatli emas yoki muomalaga layoqati cheklangan deb e'lon qilish;
A44: d) Mikromoliya tashkilotiga ushbu Shartnomaning 3.1.-bandida ko‘zda tutilgan hisobotlar, axborotlar va boshqa ma'lumotlarni o‘z vaqtida taqdim etmaslik, shuningdek, moliya-xo‘jalik faoliyat va daromad to‘g‘risidagi hisobotning ishonchsizligi holatlari aniqlanganda;
A45: e) Qarz oluvchi tomonidan ushbu shartnoma shartlariga amal qilmaslik;
...

Sheet buyruq
A4: =""&malumot!B153&" ijrochi direktorining "&malumot!B171&"dagi "&malumot!B170&"-sonli buyrug‘i" -> «CLEVER MIKROMOLIYA TASHKILOTI» MChJ ijrochi direktorining 24 mart 2025 y.dagi №659-SR-sonli buyrug‘i
A8: ="Men, Abduraximov Nadirbek Kamilevich "&malumot!B153&" ijrochi direktori, jismoniy shaxs "&malumot!B10&"ga quyidagi shartlarda "&malumot!B65&" berishni buyuraman:" -> Men, Abduraximov Nadirbek Kamilevich «CLEVER MIKROMOLIYA TASHKILOTI» MChJ ijrochi direktori, jismoniy shaxs SHAYMARDANOVA SABOXAT YULDASHEVNAga quyidagi shartlarda mikroqarz berishni buyuraman:
A9: ='Кредитная заявка'!A13:D13 -> Mikroqarz summasi: 52 000 000,00 (ellik ikki million so'm) so'm.
A10: ='Кредитная заявка'!A14:D14 -> Mikroqarz muddati: 36 (o'ttiz olti) oy.
A11: ='Кредитная заявка'!A15:D15 -> Mikroqarzdan foydalanganlik uchun foiz stavkasi: yillik 60% (Oltmish) foiz
A12: ='Кредитная заявка'!A16:D16 -> Mikroqarz bo'yicha asosiy qarz va foizlarni to'lash:
A13: ='Кредитная заявка'!A17:D17 -> - mikroqarz shartnomasi bo'yicha har oy differensial to'lovlari amalga oshiriladi
A14: ='Кредитная заявка'!A19:D19 -> - mikroqarz shartnomasi bo'yicha har oy differensial to'lovlari amalga oshiriladi
A15: =IF(malumot!B109="Avtotransport",buyruq!A14:E14,buyruq!A13:E13) -> - mikroqarz shartnomasi bo'yicha har oy differensial to'lovlari amalga oshiriladi
A16: =IF(malumot!B109=malumot!D109,""&malumot!C123&"ga tegishli "&malumot!C132&" ko'rinishidagi ko'chmas mulkni quyidagi ma'lumotlarga muvofiq garovga qabul qilinsin:",""&malumot!B123&"ga tegishli "&malumot!B131&" ko'rinishidagi transport vositasini quyidagi ma'lumotlarga muvofiq garovga qabul qilinsin:") -> XUDOYKULOV ALMURAT KURBONAZAROVICHga tegishli LADA VESTA ko'rinishidagi transport vositasini quyidagi ma'lumotlarga muvofiq garovga qabul qilinsin:
A17: =""&malumot!C123&"ga tegishli "&malumot!C132&" ko'rinishidagi ko'chmas mulkni quyidagi ma'lumotlarga muvofiq garovga qabul qilinsin:" -> 0ga tegishli 3 - xonali yakka tartibdagi uy-joy ko'rinishidagi ko'chmas mulkni quyidagi ma'lumotlarga muvofiq garovga qabul qilinsin:
A18: =""&malumot!B123&"ga tegishli "&malumot!B131&" ko'rinishidagi transport vositasini quyidagi ma'lumotlarga muvofiq garovga qabul qilinsin:" -> XUDOYKULOV ALMURAT KURBONAZAROVICHga tegishli LADA VESTA ko'rinishidagi transport vositasini quyidagi ma'lumotlarga muvofiq garovga qabul qilinsin:
A19: =dalolatnoma!A29 -> Nomi | B19: =dalolatnoma!B29 -> Kuzov turi va kuzov raqami* | C19: =dalolatnoma!C29 -> Dvigatel va shassi raqami* | D19: =dalolatnoma!D29 -> Ishlab chiqarilgan yili va rangi* | E19: =dalolatnoma!E29 -> Kelishilgan garov qiymati, so'm
A20: =dalolatnoma!A30 -> LADA VESTA | B20: =dalolatnoma!B30 -> kuzov turi - YENGIL SEDAN, kuzov raqami XTAGFL110KY258232 | C20: =dalolatnoma!C30 -> dvigatel raqami 3977458, shassi raqami - RAKAMSIZ | D20: =dalolatnoma!D30 -> rangi - SARIQ JELTO- ORANJEVIY, ishlab chiqarilgan yili - 2019 | E20: =dalolatnoma!E30 -> 78 000 000,00 (yetmish sakkiz million so'm)
A21: =dalolatnoma!A22:E22 -> -* avtotransport egasi: XUDOYKULOV ALMURAT KURBONAZAROVICH
A22: =dalolatnoma!A23:E23 -> -* texnik pasport: AAG 3367573 24.01.2024 y.
A23: =dalolatnoma!A24:E24 -> -* roʻyxatdan oʻtgan manzili/garaj manzili: SURXONDARYO VILOYATI JARQO'RG'ON TUMANI OQQURG'ON QFY QORAYONTOQ MFY IBN SINO KO'CHASI 114-UY
A24: =dalolatnoma!A25:E25 -> -* davlat raqami: 75M497WA
B25: «CLEVER MIKROMOLIYA TASHKILOTI» MChJ
B26: Ijrochi direktori
B27: N. Abduraximov

Sheet bayonnoma
A1: =""&malumot!B153&" mikromoliya tashkiloti Kredit qo‘mitasining yig‘ilishi" -> «CLEVER MIKROMOLIYA TASHKILOTI» MChJ mikromoliya tashkiloti Kredit qo‘mitasining yig‘ilishi
A2: =""&H7&" protokolidan ko'chirma" -> №659-SR protokolidan ko'chirma
A3: Toshkent shahri | E3: =malumot!B68 -> 24 mart 2025 y.
B4: KUN TARTIBI:
A5: =" "&H8&"."&malumot!B5&" ga "&malumot!B65&" berish masalasini ko‘rib chiqish to‘g‘risida." -> 1.SHAYMARDANOVA SABOXAT YULDASHEVNA ga mikroqarz berish masalasini ko‘rib chiqish to‘g‘risida.
A7: =" "&H9&" masala yuzasidan: «Clever Mikromoliya Tashkiloti» MChJ mikromoliya tashkiloti kredit bo‘yicha menejeri "&malumot!B5&"ga "&FIXED(malumot!B75)&" ("&malumot!B76&") so‘m miqdorida, muddati "&malumot!B81&" ("&malumot!B82&") oyga va yillik 60 (Oltmish) foiz miqdorida "&malumot!B65&" berich bo‘yicha "&malumot!B5&"ning kredit arizasi va "&malumot!B153&"ning xulosasi bilan ishtirokchilarni tanishtirdi." -> Birinchi masala yuzasidan: «Clever Mikromoliya Tashkiloti» MChJ mikromoliya tashkiloti kredit bo‘yicha menejeri SHAYMARDANOVA SABOXAT YULDASHEVNAga 52 000 000,00 (ellik ikki million so'm) so‘m miqdorida, muddati 36 (o'ttiz olti) oyga va yillik 60 (Oltmish) foiz miqdorida mikroqarz berich bo‘yicha SHAYMARDANOVA SABOXAT YULDASHEVNAning kredit arizasi va «CLEVER MIKROMOLIYA TASHKILOTI» MChJning xulosasi bilan ishtirokchilarni tanishtirdi. | G7: Protokol raqami | H7: =malumot!B1 -> №659-SR
G8: Savol raqami | H8: 1 | I8: 1 | J8: 2 | K8: 3 | L8: 4 | M8: 5 | N8: 6 | O8: 7 | P8: 8 | Q8: 9 | R8: 10 | S8: 11 | T8: 12 | U8: 13 | V8: 14 | W8: 15 | X8: 16 | Y8: 17 | Z8: 18 | AA8: 19 | AB8: 20 | AC8: 21 | AD8: 22 | AE8: 23 | AF8: 24 | AG8: 25
G9: Savol raqami qol bilan | H9: =IF(H8=I8,I9,IF(H8=J8,J9,IF(H8=K8,K9,IF(H8=L8,L9,IF(H8=M8,M9,IF(H8=N8,N9,IF(H8=O8,O9,IF(H8=P8,P9,IF(H8=Q8,Q9,IF(H8=R8,R9,IF(H8=S8,S9,IF(H8=T8,T9,IF(H8=U8,U9,IF(H8=V8,V9,IF(H8=W8,W9,IF(H8=X8,X9,IF(H8=Y8,Y9,IF(H8=Z8,Z9,IF(H8=AA8,AA9,IF(H8=AB8,AB9,IF(H8=AC8,AC9,IF(H8=AD8,AD9,IF(H8=AE8,AE9,IF(H8=AF8,AF9,IF(H8=AG8,AG9))))))))))))))))))))))))) -> Birinchi | I9: Birinchi | J9: Ikkinchi | K9: Uchinchi | L9: To'rtinchi | M9: Beshinchi | N9: O'ltinchi | O9: Yettinchi | P9: Sakkizinchi | Q9: Tuqqizinchi | R9: O'ninchi | S9: O'n birinchi | T9: O'n ikkinchi | U9: O'n uchinchi | V9: O'n to'rtinchi | W9: O'n beshinchi | X9: O'n oltinchi | Y9: O'n yettinchi | Z9: O'n sakkizinchi | AA9: O'n tuqqizinchi | AB9: Yigirmanchi | AC9: Yigirma birinchi | AD9: Yigizma ikkinchi | AE9: Yigirma uchinchi | AF9: Yigirma to'rtinchi | AG9: Yigirma beshinchi
A14: =""&malumot!C64&" ta’minoti:" -> Mikroqarz ta’minoti:
A16: =xulosa!A18:E18 -> Egalik huquqi XUDOYKULOV ALMURAT KURBONAZAROVICHga tegishli bo'lgan garovga olingan avtomobil markasi LADA VESTA, rangi - SARIQ JELTO- ORANJEVIY, ishlab chiqarilgan yili - 2019, davlat raqam belgisi 75M497WA, kuzov turi - YENGIL SEDAN, kuzov raqami XTAGFL110KY258232, dvigatel raqami 3977458, shassi raqami - RAKAMSIZ
C17: masala yuzasidan berilgan ma’lumotlarni muhokama qilib, Kredit qo‘mitasi a’zolariga taqdim etilgan zarur hujjatlarni o‘rganib, majlisda ishtirok etgan Kredit qo‘mitasi a’zolarining taklif va mulohazalarini inobatga olgan holda | D17: =""&malumot!B153&" kredit qo‘mitasi" -> «CLEVER MIKROMOLIYA TASHKILOTI» MChJ kredit qo‘mitasi | E17: =CONCATENATE(C17,D17) -> masala yuzasidan berilgan ma’lumotlarni muhokama qilib, Kredit qo‘mitasi a’zolariga taqdim etilgan zarur hujjatlarni o‘rganib, majlisda ishtirok etgan Kredit qo‘mitasi a’zolarining taklif va mulohazalarini inobatga olgan holda «CLEVER MIKROMOLIYA TASHKILOTI» MChJ kredit qo‘mitasi
A18: =CONCATENATE(H9,E17) -> Birinchi masala yuzasidan berilgan ma’lumotlarni muhokama qilib, Kredit qo‘mitasi a’zolariga taqdim etilgan zarur hujjatlarni o‘rganib, majlisda ishtirok etgan Kredit qo‘mitasi a’zolarining taklif va mulohazalarini inobatga olgan holda «CLEVER MIKROMOLIYA TASHKILOTI» MChJ kredit qo‘mitasi
A19: QAROR QILADI:
A20: =" "&malumot!B5&"ga quyidagi shartlarda "&malumot!B65&" berish masalasi ma’qullansin:" -> SHAYMARDANOVA SABOXAT YULDASHEVNAga quyidagi shartlarda mikroqarz berish masalasi ma’qullansin:
A21: ="1. "&malumot!C64&" summasi: "&FIXED(malumot!B75)&" ("&malumot!B76&") so'm." -> 1. Mikroqarz summasi: 52 000 000,00 (ellik ikki million so'm) so'm.
A22: ="2. "&malumot!C64&" muddati: "&malumot!B81&" ("&malumot!B82&") oy " -> 2. Mikroqarz muddati: 36 (o'ttiz olti) oy
A23: ="3. "&malumot!C64&"dan foydalanganlik uchun foiz stavkasi:yillik "&malumot!B85&"% ("&malumot!B86&") foiz." -> 3. Mikroqarzdan foydalanganlik uchun foiz stavkasi:yillik 60% (Oltmish) foiz.
A24: ="4. "&malumot!C64&" bo‘yicha asosiy qarz va foizlarni to‘lash:" -> 4. Mikroqarz bo‘yicha asosiy qarz va foizlarni to‘lash:
A25: ='Кредитная заявка'!A19:D19 -> - mikroqarz shartnomasi bo'yicha har oy differensial to'lovlari amalga oshiriladi
A26: ="5. "&malumot!C64&" bo‘yicha garov "&xulosa!A29:E29&"" -> 5. Mikroqarz bo‘yicha garov - XUDOYKULOV ALMURAT KURBONAZAROVICH ga mulk huquqi asosida tegishli avtotransport vositasi LADA VESTA , quyidagi tafsilotlarga muvofiq:
A27: =dalolatnoma!A29 -> Nomi | B27: =dalolatnoma!B29 -> Kuzov turi va kuzov raqami* | C27: =dalolatnoma!C29 -> Dvigatel va shassi raqami* | D27: =dalolatnoma!D29 -> Ishlab chiqarilgan yili va rangi* | E27: =dalolatnoma!E29 -> Kelishilgan garov qiymati, so'm
A28: =dalolatnoma!A30 -> LADA VESTA | B28: =dalolatnoma!B30 -> kuzov turi - YENGIL SEDAN, kuzov raqami XTAGFL110KY258232 | C28: =dalolatnoma!C30 -> dvigatel raqami 3977458, shassi raqami - RAKAMSIZ | D28: =dalolatnoma!D30 -> rangi - SARIQ JELTO- ORANJEVIY, ishlab chiqarilgan yili - 2019 | E28: =dalolatnoma!E30 -> 78 000 000,00 (yetmish sakkiz million so'm)
A29: =dalolatnoma!A22:E22 -> -* avtotransport egasi: XUDOYKULOV ALMURAT KURBONAZAROVICH
A30: =dalolatnoma!A23:E23 -> -* texnik pasport: AAG 3367573 24.01.2024 y.
A31: =dalolatnoma!A24:E24 -> -* roʻyxatdan oʻtgan manzili/garaj manzili: SURXONDARYO VILOYATI JARQO'RG'ON TUMANI OQQURG'ON QFY QORAYONTOQ MFY IBN SINO KO'CHASI 114-UY
A32: =dalolatnoma!A25:E25 -> -* davlat raqami: 75M497WA
A34: ="6. Boshqa shartlar – "&IF(malumot!B109=malumot!B110,"avtotransport vositasi",IF(malumot!B109=malumot!C110,"ko'chmas mulk",0))&" shaklida garov ta'minlangandan keyin "&malumot!B65&" berish." -> 6. Boshqa shartlar – 0 shaklida garov ta'minlangandan keyin mikroqarz berish.
A36: Qaror bir ovozdan qabul qilindi.
B37: =malumot!B153&" ijrochi direktori" -> «CLEVER MIKROMOLIYA TASHKILOTI» MChJ ijrochi direktori | D37: N. Abduraximov
B38: =malumot!A165 -> Kreditlash bo’limi boshlig’i | D38: =malumot!B165 -> B. Mominov
B39: =malumot!A166 -> Monitoring bo’limi boshlig’i | D39: =malumot!B166 -> B. Jumanazarov

Sheet График дифференц
E1: Приложение №1
F2: ="к договору микрозайма "&malumot!B74&"" -> к договору микрозайма 24 mart 2025 y.dan №659-SR
A4: График погашения
L5: =malumot!B81 -> 36
A6: № | B6: Дата погашения | C6: Остаток основного долга | D6: Сумма погашения, сум
D7: основного долга | E7: процентов* | F7: всего*
A8: 1 | B8: =malumot!B79 -> 45748 | C8: =malumot!B75 -> 52000000 | D8: =IF(IF(C8=0,L8,IF(C8>1,I8))="",0,(IF(C8=0,L8,IF(C8>1,I8)))) -> 1444444.4 | E8: =IF(C8=0,N6,IF(C8>1,L8)) -> 683835.6 | F8: =IF(C8=0,O6,IF(C8>1,M8)) -> 2128280 | G8: =B8-malumot!B67 -> 8 | H8: =DATE(YEAR(B8),12,31)-DATE(YEAR(B8),1,1)+1 -> 365 | I8: =IF(malumot!B83=0,ROUND(C8/L5,2),"") -> 1444444.4 | L8: =ROUND(C8*malumot!$B$84/H8,2)*G8 -> 683835.6 | M8: =D8+E8 -> 2128280 | O8: =TEXT(B8,"ддд") -> Вт | P8: =IF(O8=$U$8,2,IF(O8=$V$8,1,0)) -> 0 | Q8: =DAY(malumot!$B$78)+P8 -> 1 | S8: Чт | T8: Пт | U8: Сб | V8: Вс
A9: 2 | B9: =IF(A9<=malumot!$B$81,DATE(YEAR(R9),MONTH(R9),DAY(IF(A9=malumot!$B$81,malumot!$B$67,IF(A9<malumot!$B$81,(Q9),IF(A9>malumot!$B$81,$H$44,0)))))) -> 45778 | C9: =C8-D8 -> 50555556 | D9: =IF(C9=0,L9,IF(C9>1,I9)) -> 1444444.4 | E9: =IF(C9=0,N8,IF(C9>1,L9)) -> 2493150.6 | F9: =IF(C9=0,N8,IF(C9>1,M9)) -> 3937595 | G9: =B9-B8 -> 30 | H9: =DATE(YEAR(B9),12,31)-DATE(YEAR(B9),1,1)+1 -> 365 | I9: =IF(I8="",ROUND(C8/(L5-1),2),I8) -> 1444444.4 | L9: =ROUND(C9*malumot!$B$84/H9,2)*G9 -> 2493150.6 | M9: =D9+E9 -> 3937595 | O9: =TEXT(R9,"ддд") -> Чт | P9: =IF(O9=$U$8,2,IF(O9=$V$8,1,0)) -> 0 | Q9: =DAY(malumot!$B$78)+P9 -> 1 | R9: =IF(A9<=malumot!$B$81,DATE(YEAR($B$8),MONTH($B$8)+A8,DAY(malumot!$B$78)),0) -> 45778
A10: 3 | B10: =IF(A10<=malumot!$B$81,DATE(YEAR(R10),MONTH(R10),DAY(IF(A10=malumot!$B$81,malumot!$B$67,IF(A10<malumot!$B$81,(Q10),IF(A10>malumot!$B$81,$H$44,0)))))) -> 45810 | C10: =C9-D9 -> 49111111 | D10: =IF(C10=0,L10,IF(C10>1,I10)) -> 1444444.4 | E10: =IF(C10=0,N9,IF(C10>1,L10)) -> 2583378.9 | F10: =IF(C10=0,N9,IF(C10>1,M10)) -> 4027823.3 | G10: =B10-B9 -> 32 | H10: =DATE(YEAR(B10),12,31)-DATE(YEAR(B10),1,1)+1 -> 365 | I10: =I9 -> 1444444.4 | L10: =ROUND(C10*malumot!$B$84/H10,2)*G10 -> 2583378.9 | M10: =D10+E10 -> 4027823.3 | O10: =TEXT(R10,"ддд") -> Вс | P10: =IF(O10=$U$8,2,IF(O10=$V$8,1,0)) -> 1 | Q10: =DAY(malumot!$B$78)+P10 -> 2 | R10: =IF(A10<=malumot!$B$81,DATE(YEAR($B$8),MONTH($B$8)+A9,DAY(malumot!$B$78)),0) -> 45809
A11: 4 | B11: =IF(A11<=malumot!$B$81,DATE(YEAR(R11),MONTH(R11),DAY(IF(A11=malumot!$B$81,malumot!$B$67,IF(A11<malumot!$B$81,(Q11),IF(A11>malumot!$B$81,$H$44,0)))))) -> 45839 | C11: =C10-D10 -> 47666667 | D11: =IF(C11=0,L11,IF(C11>1,I11)) -> 1444444.4 | E11: =IF(C11=0,N10,IF(C11>1,L11)) -> 2272328.6 | F11: =IF(C11=0,N10,IF(C11>1,M11)) -> 3716773.1 | G11: =B11-B10 -> 29 | H11: =DATE(YEAR(B11),12,31)-DATE(YEAR(B11),1,1)+1 -> 365 | I11: =I10 -> 1444444.4 | L11: =ROUND(C11*malumot!$B$84/H11,2)*G11 -> 2272328.6 | M11: =D11+E11 -> 3716773.1 | O11: =TEXT(R11,"ддд") -> Вт | P11: =IF(O11=$U$8,2,IF(O11=$V$8,1,0)) -> 0 | Q11: =DAY(malumot!$B$78)+P11 -> 1 | R11: =IF(A11<=malumot!$B$81,DATE(YEAR($B$8),MONTH($B$8)+A10,DAY(malumot!$B$78)),0) -> 45839
A12: 5 | B12: =IF(A12<=malumot!$B$81,DATE(YEAR(R12),MONTH(R12),DAY(IF(A12=malumot!$B$81,malumot!$B$67,IF(A12<malumot!$B$81,(Q12),IF(A12>malumot!$B$81,$H$44,0)))))) -> 45870 | C12: =C11-D11 -> 46222222 | D12: =IF(C12=0,L12,IF(C12>1,I12)) -> 1444444.4 | E12: =IF(C12=0,N11,IF(C12>1,L12)) -> 2355433.9 | F12: =IF(C12=0,N11,IF(C12>1,M12)) -> 3799878.4 | G12: =B12-B11 -> 31 | H12: =DATE(YEAR(B12),12,31)-DATE(YEAR(B12),1,1)+1 -> 365 | I12: =I11 -> 1444444.4 | J12: =malumot!B75 -> 52000000 | L12: =ROUND(C12*malumot!$B$84/H12,2)*G12 -> 2355433.9 | M12: =D12+E12 -> 3799878.4 | O12: =TEXT(R12,"ддд") -> Пт | P12: =IF(O12=$U$8,2,IF(O12=$V$8,1,0)) -> 0 | Q12: =DAY(malumot!$B$78)+P12 -> 1 | R12: =IF(A12<=malumot!$B$81,DATE(YEAR($B$8),MONTH($B$8)+A11,DAY(malumot!$B$78)),0) -> 45870
A13: 6 | B13: =IF(A13<=malumot!$B$81,DATE(YEAR(R13),MONTH(R13),DAY(IF(A13=malumot!$B$81,malumot!$B$67,IF(A13<malumot!$B$81,(Q13),IF(A13>malumot!$B$81,$H$44,0)))))) -> 45901 | C13: =C12-D12 -> 44777778 | D13: =IF(C13=0,L13,IF(C13>1,I13)) -> 1444444.4 | E13: =IF(C13=0,N12,IF(C13>1,L13)) -> 2281826.6 | F13: =IF(C13=0,N12,IF(C13>1,M13)) -> 3726271 | G13: =B13-B12 -> 31 | H13: =DATE(YEAR(B13),12,31)-DATE(YEAR(B13),1,1)+1 -> 365 | I13: =IF(L5=H1,K13,IF(L5>H1,I12)) -> 1444444.4 | J13: =SUM($I$8:I12) -> 7222222.2 | K13: =$J$12-J13 -> 44777778 | L13: =ROUND(C13*malumot!$B$84/H13,2)*G13 -> 2281826.6 | M13: =D13+E13 -> 3726271 | O13: =TEXT(R13,"ддд") -> Пн | P13: =IF(O13=$U$8,2,IF(O13=$V$8,1,0)) -> 0 | Q13: =DAY(malumot!$B$78)+P13 -> 1 | R13: =IF(A13<=malumot!$B$81,DATE(YEAR($B$8),MONTH($B$8)+A12,DAY(malumot!$B$78)),0) -> 45901
A14: 7 | B14: =IF(A14<=malumot!$B$81,DATE(YEAR(R14),MONTH(R14),DAY(IF(A14=malumot!$B$81,malumot!$B$67,IF(A14<malumot!$B$81,(Q14),IF(A14>malumot!$B$81,$H$44,0)))))) -> 45931 | C14: =C13-D13 -> 43333333 | D14: =IF(C14=0,L14,IF(C14>1,I14)) -> 1444444.4 | E14: =IF(C14=0,N13,IF(C14>1,L14)) -> 2136986.4 | F14: =IF(C14=0,N13,IF(C14>1,M14)) -> 3581430.8 | G14: =B14-B13 -> 30 | H14: =DATE(YEAR(B14),12,31)-DATE(YEAR(B14),1,1)+1 -> 365 | I14: =IF($L$5=A14,K14,IF($L$5>A14,I13)) -> 1444444.4 | J14: =SUM($I$8:I13) -> 8666666.6 | K14: =$J$12-J14 -> 43333333 | L14: =ROUND(C14*malumot!$B$84/H14,2)*G14 -> 2136986.4 | M14: =D14+E14 -> 3581430.8 | O14: =TEXT(R14,"ддд") -> Ср | P14: =IF(O14=$U$8,2,IF(O14=$V$8,1,0)) -> 0 | Q14: =DAY(malumot!$B$78)+P14 -> 1 | R14: =IF(A14<=malumot!$B$81,DATE(YEAR($B$8),MONTH($B$8)+A13,DAY(malumot!$B$78)),0) -> 45931
A15: 8 | B15: =IF(A15<=malumot!$B$81,DATE(YEAR(R15),MONTH(R15),DAY(IF(A15=malumot!$B$81,malumot!$B$67,IF(A15<malumot!$B$81,(Q15),IF(A15>malumot!$B$81,$H$44,0)))))) -> 45964 | C15: =C14-D14 -> 41888889 | D15: =IF(C15=0,L15,IF(C15>1,I15)) -> 1444444.4 | E15: =IF(C15=0,N14,IF(C15>1,L15)) -> 2272328.9 | F15: =IF(C15=0,N14,IF(C15>1,M15)) -> 3716773.3 | G15: =B15-B14 -> 33 | H15: =DATE(YEAR(B15),12,31)-DATE(YEAR(B15),1,1)+1 -> 365 | I15: =IF($L$5=A15,K15,IF($L$5>A15,I14)) -> 1444444.4 | J15: =SUM($I$8:I14) -> 10111111 | K15: =$J$12-J15 -> 41888889 | L15: =ROUND(C15*malumot!$B$84/H15,2)*G15 -> 2272328.9 | M15: =D15+E15 -> 3716773.3 | O15: =TEXT(R15,"ддд") -> Сб | P15: =IF(O15=$U$8,2,IF(O15=$V$8,1,0)) -> 2 | Q15: =DAY(malumot!$B$78)+P15 -> 3 | R15: =IF(A15<=malumot!$B$81,DATE(YEAR($B$8),MONTH($B$8)+A14,DAY(malumot!$B$78)),0) -> 45962
A16: 9 | B16: =IF(A16<=malumot!$B$81,DATE(YEAR(R16),MONTH(R16),DAY(IF(A16=malumot!$B$81,malumot!$B$67,IF(A16<malumot!$B$81,(Q16),IF(A16>malumot!$B$81,$H$44,0)))))) -> 45992 | C16: =C15-D15 -> 40444444 | D16: =IF(C16=0,L16,IF(C16>1,I16)) -> 1444444.4 | E16: =IF(C16=0,N15,IF(C16>1,L16)) -> 1861552.6 | F16: =IF(C16=0,N15,IF(C16>1,M16)) -> 3305997 | G16: =B16-B15 -> 28 | H16: =DATE(YEAR(B16),12,31)-DATE(YEAR(B16),1,1)+1 -> 365 | I16: =IF($L$5=A16,K16,IF($L$5>A16,I15)) -> 1444444.4 | J16: =SUM($I$8:I15) -> 11555556 | K16: =$J$12-J16 -> 40444444 | L16: =ROUND(C16*malumot!$B$84/H16,2)*G16 -> 1861552.6 | M16: =D16+E16 -> 3305997 | O16: =TEXT(R16,"ддд") -> Пн | P16: =IF(O16=$U$8,2,IF(O16=$V$8,1,0)) -> 0 | Q16: =DAY(malumot!$B$78)+P16 -> 1 | R16: =IF(A16<=malumot!$B$81,DATE(YEAR($B$8),MONTH($B$8)+A15,DAY(malumot!$B$78)),0) -> 45992
A17: 10 | B17: =IF(A17<=malumot!$B$81,DATE(YEAR(R17),MONTH(R17),DAY(IF(A17=malumot!$B$81,malumot!$B$67,IF(A17<malumot!$B$81,(Q17),IF(A17>malumot!$B$81,$H$44,0)))))) -> 46023 | C17: =C16-D16 -> 39000000 | D17: =IF(C17=0,L17,IF(C17>1,I17)) -> 1444444.4 | E17: =IF(C17=0,N16,IF(C17>1,L17)) -> 1987397.3 | F17: =IF(C17=0,N16,IF(C17>1,M17)) -> 3431841.7 | G17: =B17-B16 -> 31 | H17: =DATE(YEAR(B17),12,31)-DATE(YEAR(B17),1,1)+1 -> 365 | I17: =IF($L$5=A17,K17,IF($L$5>A17,I16)) -> 1444444.4 | J17: =SUM($I$8:I16) -> 13000000 | K17: =$J$12-J17 -> 39000000 | L17: =ROUND(C17*malumot!$B$84/H17,2)*G17 -> 1987397.3 | M17: =D17+E17 -> 3431841.7 | O17: =TEXT(R17,"ддд") -> Чт | P17: =IF(O17=$U$8,2,IF(O17=$V$8,1,0)) -> 0 | Q17: =DAY(malumot!$B$78)+P17 -> 1 | R17: =IF(A17<=malumot!$B$81,DATE(YEAR($B$8),MONTH($B$8)+A16,DAY(malumot!$B$78)),0) -> 46023
A18: 11 | B18: =IF(A18<=malumot!$B$81,DATE(YEAR(R18),MONTH(R18),DAY(IF(A18=malumot!$B$81,malumot!$B$67,IF(A18<malumot!$B$81,(Q18),IF(A18>malumot!$B$81,$H$44,0)))))) -> 46055 | C18: =C17-D17 -> 37555556 | D18: =IF(C18=0,L18,IF(C18>1,I18)) -> 1444444.4 | E18: =IF(C18=0,N17,IF(C18>1,L18)) -> 1975525.1 | F18: =IF(C18=0,N17,IF(C18>1,M18)) -> 3419969.6 | G18: =B18-B17 -> 32 | H18: =DATE(YEAR(B18),12,31)-DATE(YEAR(B18),1,1)+1 -> 365 | I18: =IF($L$5=A18,K18,IF($L$5>A18,I17)) -> 1444444.4 | J18: =SUM($I$8:I17) -> 14444444 | K18: =$J$12-J18 -> 37555556 | L18: =ROUND(C18*malumot!$B$84/H18,2)*G18 -> 1975525.1 | M18: =D18+E18 -> 3419969.6 | O18: =TEXT(R18,"ддд") -> Вс | P18: =IF(O18=$U$8,2,IF(O18=$V$8,1,0)) -> 1 | Q18: =DAY(malumot!$B$78)+P18 -> 2 | R18: =IF(A18<=malumot!$B$81,DATE(YEAR($B$8),MONTH($B$8)+A17,DAY(malumot!$B$78)),0) -> 46054
A19: 12 | B19: =IF(A19<=malumot!$B$81,DATE(YEAR(R19),MONTH(R19),DAY(IF(A19=malumot!$B$81,malumot!$B$67,IF(A19<malumot!$B$81,(Q19),IF(A19>malumot!$B$81,$H$44,0)))))) -> 46083 | C19: =C18-D18 -> 36111111 | D19: =IF(C19=0,L19,IF(C19>1,I19)) -> 1444444.4 | E19: =IF(C19=0,N18,IF(C19>1,L19)) -> 1662100.4 | F19: =IF(C19=0,N18,IF(C19>1,M19)) -> 3106544.9 | G19: =B19-B18 -> 28 | H19: =DATE(YEAR(B19),12,31)-DATE(YEAR(B19),1,1)+1 -> 365 | I19: =IF($L$5=A19,K19,IF($L$5>A19,I18)) -> 1444444.4 | J19: =SUM($I$8:I18) -> 15888889 | K19: =$J$12-J19 -> 36111111 | L19: =ROUND(C19*malumot!$B$84/H19,2)*G19 -> 1662100.4 | M19: =D19+E19 -> 3106544.9 | O19: =TEXT(R19,"ддд") -> Вс | P19: =IF(O19=$U$8,2,IF(O19=$V$8,1,0)) -> 1 | Q19: =DAY(malumot!$B$78)+P19 -> 2 | R19: =IF(A19<=malumot!$B$81,DATE(YEAR($B$8),MONTH($B$8)+A18,DAY(malumot!$B$78)),0) -> 46082
A20: 13 | B20: =IF(A20<=malumot!$B$81,DATE(YEAR(R20),MONTH(R20),DAY(IF(A20=malumot!$B$81,malumot!$B$67,IF(A20<malumot!$B$81,(Q20),IF(A20>malumot!$B$81,$H$44,0)))))) -> 46113 | C20: =C19-D19 -> 34666667 | D20: =IF(C20=0,L20,IF(C20>1,I20)) -> 1444444.4 | E20: =IF(C20=0,N19,IF(C20>1,L20)) -> 1709589 | F20: =IF(C20=0,N19,IF(C20>1,M20)) -> 3154033.4 | G20: =B20-B19 -> 30 | H20: =DATE(YEAR(B20),12,31)-DATE(YEAR(B20),1,1)+1 -> 365 | I20: =IF($L$5=A20,K20,IF($L$5>A20,I19)) -> 1444444.4 | J20: =SUM($I$8:I19) -> 17333333 | K20: =$J$12-J20 -> 34666667 | L20: =ROUND(C20*malumot!$B$84/H20,2)*G20 -> 1709589 | M20: =D20+E20 -> 3154033.4 | O20: =TEXT(R20,"ддд") -> Ср | P20: =IF(O20=$U$8,2,IF(O20=$V$8,1,0)) -> 0 | Q20: =DAY(malumot!$B$78)+P20 -> 1 | R20: =IF(A20<=malumot!$B$81,DATE(YEAR($B$8),MONTH($B$8)+A19,DAY(malumot!$B$78)),0) -> 46113
A21: 14 | B21: =IF(A21<=malumot!$B$81,DATE(YEAR(R21),MONTH(R21),DAY(IF(A21=malumot!$B$81,malumot!$B$67,IF(A21<malumot!$B$81,(Q21),IF(A21>malumot!$B$81,$H$44,0)))))) -> 46143 | C21: =C20-D20 -> 33222222 | D21: =IF(C21=0,L21,IF(C21>1,I21)) -> 1444444.4 | E21: =IF(C21=0,N20,IF(C21>1,L21)) -> 1638356.1 | F21: =IF(C21=0,N20,IF(C21>1,M21)) -> 3082800.5 | G21: =B21-B20 -> 30 | H21: =DATE(YEAR(B21),12,31)-DATE(YEAR(B21),1,1)+1 -> 365 | I21: =IF($L$5=A21,K21,IF($L$5>A21,I20)) -> 1444444.4 | J21: =SUM($I$8:I20) -> 18777778 | K21: =$J$12-J21 -> 33222222 | L21: =ROUND(C21*malumot!$B$84/H21,2)*G21 -> 1638356.1 | M21: =D21+E21 -> 3082800.5 | O21: =TEXT(R21,"ддд") -> Пт | P21: =IF(O21=$U$8,2,IF(O21=$V$8,1,0)) -> 0 | Q21: =DAY(malumot!$B$78)+P21 -> 1 | R21: =IF(A21<=malumot!$B$81,DATE(YEAR($B$8),MONTH($B$8)+A20,DAY(malumot!$B$78)),0) -> 46143
A22: 15 | B22: =IF(A22<=malumot!$B$81,DATE(YEAR(R22),MONTH(R22),DAY(IF(A22=malumot!$B$81,malumot!$B$67,IF(A22<malumot!$B$81,(Q22),IF(A22>malumot!$B$81,$H$44,0)))))) -> 46174 | C22: =C21-D21 -> 31777778 | D22: =IF(C22=0,L22,IF(C22>1,I22)) -> 1444444.4 | E22: =IF(C22=0,N21,IF(C22>1,L22)) -> 1619360.6 | F22: =IF(C22=0,N21,IF(C22>1,M22)) -> 3063805.1 | G22: =B22-B21 -> 31 | H22: =DATE(YEAR(B22),12,31)-DATE(YEAR(B22),1,1)+1 -> 365 | I22: =IF($L$5=A22,K22,IF($L$5>A22,I21)) -> 1444444.4 | J22: =SUM($I$8:I21) -> 20222222 | K22: =$J$12-J22 -> 31777778 | L22: =ROUND(C22*malumot!$B$84/H22,2)*G22 -> 1619360.6 | M22: =D22+E22 -> 3063805.1 | O22: =TEXT(R22,"ддд") -> Пн | P22: =IF(O22=$U$8,2,IF(O22=$V$8,1,0)) -> 0 | Q22: =DAY(malumot!$B$78)+P22 -> 1 | R22: =IF(A22<=malumot!$B$81,DATE(YEAR($B$8),MONTH($B$8)+A21,DAY(malumot!$B$78)),0) -> 46174
A23: 16 | B23: =IF(A23<=malumot!$B$81,DATE(YEAR(R23),MONTH(R23),DAY(IF(A23=malumot!$B$81,malumot!$B$67,IF(A23<malumot!$B$81,(Q23),IF(A23>malumot!$B$81,$H$44,0)))))) -> 46204 | C23: =C22-D22 -> 30333333 | D23: =IF(C23=0,L23,IF(C23>1,I23)) -> 1444444.4 | E23: =IF(C23=0,N22,IF(C23>1,L23)) -> 1495890.3 | F23: =IF(C23=0,N22,IF(C23>1,M23)) -> 2940334.7 | G23: =B23-B22 -> 30 | H23: =DATE(YEAR(B23),12,31)-DATE(YEAR(B23),1,1)+1 -> 365 | I23: =IF($L$5=A23,K23,IF($L$5>A23,I22)) -> 1444444.4 | J23: =SUM($I$8:I22) -> 21666667 | K23: =$J$12-J23 -> 30333333 | L23: =ROUND(C23*malumot!$B$84/H23,2)*G23 -> 1495890.3 | M23: =D23+E23 -> 2940334.7 | O23: =TEXT(R23,"ддд") -> Ср | P23: =IF(O23=$U$8,2,IF(O23=$V$8,1,0)) -> 0 | Q23: =DAY(malumot!$B$78)+P23 -> 1 | R23: =IF(A23<=malumot!$B$81,DATE(YEAR($B$8),MONTH($B$8)+A22,DAY(malumot!$B$78)),0) -> 46204
A24: 17 | B24: =IF(A24<=malumot!$B$81,DATE(YEAR(R24),MONTH(R24),DAY(IF(A24=malumot!$B$81,malumot!$B$67,IF(A24<malumot!$B$81,(Q24),IF(A24>malumot!$B$81,$H$44,0)))))) -> 46237 | C24: =C23-D23 -> 28888889 | D24: =IF(C24=0,L24,IF(C24>1,I24)) -> 1444444.4 | E24: =IF(C24=0,N23,IF(C24>1,L24)) -> 1567123.1 | F24: =IF(C24=0,N23,IF(C24>1,M24)) -> 3011567.6 | G24: =B24-B23 -> 33 | H24: =DATE(YEAR(B24),12,31)-DATE(YEAR(B24),1,1)+1 -> 365 | I24: =IF($L$5=A24,K24,IF($L$5>A24,I23)) -> 1444444.4 | J24: =SUM($I$8:I23) -> 23111111 | K24: =$J$12-J24 -> 28888889 | L24: =ROUND(C24*malumot!$B$84/H24,2)*G24 -> 1567123.1 | M24: =D24+E24 -> 3011567.6 | O24: =TEXT(R24,"ддд") -> Сб | P24: =IF(O24=$U$8,2,IF(O24=$V$8,1,0)) -> 2 | Q24: =DAY(malumot!$B$78)+P24 -> 3 | R24: =IF(A24<=malumot!$B$81,DATE(YEAR($B$8),MONTH($B$8)+A23,DAY(malumot!$B$78)),0) -> 46235
A25: 18 | B25: =IF(A25<=malumot!$B$81,DATE(YEAR(R25),MONTH(R25),DAY(IF(A25=malumot!$B$81,malumot!$B$67,IF(A25<malumot!$B$81,(Q25),IF(A25>malumot!$B$81,$H$44,0)))))) -> 46266 | C25: =C24-D24 -> 27444445 | D25: =IF(C25=0,L25,IF(C25>1,I25)) -> 1444444.4 | E25: =IF(C25=0,N24,IF(C25>1,L25)) -> 1308310.6 | F25: =IF(C25=0,N24,IF(C25>1,M25)) -> 2752755.1 | G25: =B25-B24 -> 29 | H25: =DATE(YEAR(B25),12,31)-DATE(YEAR(B25),1,1)+1 -> 365 | I25: =IF($L$5=A25,K25,IF($L$5>A25,I24)) -> 1444444.4 | J25: =SUM($I$8:I24) -> 24555555 | K25: =$J$12-J25 -> 27444445 | L25: =ROUND(C25*malumot!$B$84/H25,2)*G25 -> 1308310.6 | M25: =D25+E25 -> 2752755.1 | O25: =TEXT(R25,"ддд") -> Вт | P25: =IF(O25=$U$8,2,IF(O25=$V$8,1,0)) -> 0 | Q25: =DAY(malumot!$B$78)+P25 -> 1 | R25: =IF(A25<=malumot!$B$81,DATE(YEAR($B$8),MONTH($B$8)+A24,DAY(malumot!$B$78)),0) -> 46266
... A31: 24 | B31: =IF(A31<=malumot!$B$81,DATE(YEAR(R31),MONTH(R31),DAY(IF(A31=malumot!$B$81,malumot!$B$67,IF(A31<malumot!$B$81,(Q31),IF(A31>malumot!$B$81,$H$44,0)))))) -> 46447 | C31: =C30-D30 -> 18777778 | D31: =IF(C31=0,L31,IF(C31>1,I31)) -> 1444444.4 | E31: =IF(C31=0,N30,IF(C31>1,L31)) -> 864292.24 | F31: =IF(C31=0,N30,IF(C31>1,M31)) -> 2308736.7 | G31: =B31-B30 -> 28 | H31: =DATE(YEAR(B31),12,31)-DATE(YEAR(B31),1,1)+1 -> 365 | I31: =IF($L$5=A31,K31,IF($L$5>A31,I30)) -> 1444444.4 | J31: =SUM($I$8:I30) -> 33222222 | K31: =$J$12-J31 -> 18777778 | L31: =ROUND(C31*malumot!$B$84/H31,2)*G31 -> 864292.24 | M31: =D31+E31 -> 2308736.7 | O31: =TEXT(R31,"ддд") -> Пн | P31: =IF(O31=$U$8,2,IF(O31=$V$8,1,0)) -> 0 | Q31: =DAY(malumot!$B$78)+P31 -> 1 | R31: =IF(A31<=malumot!$B$81,DATE(YEAR($B$8),MONTH($B$8)+A30,DAY(malumot!$B$78)),0) -> 46447
A32: =1+A31 -> 25 | B32: =IF(A32<=malumot!$B$81,DATE(YEAR(R32),MONTH(R32),DAY(IF(A32=malumot!$B$81,malumot!$B$67,IF(A32<malumot!$B$81,(Q32),IF(A32>malumot!$B$81,$H$44,0)))))) -> 46478 | C32: =C31-D31 -> 17333333 | D32: =IF(C32=0,L32,IF(C32>1,I32)) -> 1444444.4 | E32: =IF(C32=0,N31,IF(C32>1,L32)) -> 883287.65 | F32: =IF(C32=0,N31,IF(C32>1,M32)) -> 2327732.1 | G32: =B32-B31 -> 31 | H32: =DATE(YEAR(B32),12,31)-DATE(YEAR(B32),1,1)+1 -> 365 | I32: =IF($L$5=A32,K32,IF($L$5>A32,I31)) -> 1444444.4 | J32: =SUM($I$8:I31) -> 34666667 | K32: =$J$12-J32 -> 17333333 | L32: =ROUND(C32*malumot!$B$84/H32,2)*G32 -> 883287.65 | M32: =D32+E32 -> 2327732.1 | O32: =TEXT(R32,"ддд") -> Чт | P32: =IF(O32=$U$8,2,IF(O32=$V$8,1,0)) -> 0 | Q32: =DAY(malumot!$B$78)+P32 -> 1 | R32: =IF(A32<=malumot!$B$81,DATE(YEAR($B$8),MONTH($B$8)+A31,DAY(malumot!$B$78)),0) -> 46478
A33: =1+A32 -> 26 | B33: =IF(A33<=malumot!$B$81,DATE(YEAR(R33),MONTH(R33),DAY(IF(A33=malumot!$B$81,malumot!$B$67,IF(A33<malumot!$B$81,(Q33),IF(A33>malumot!$B$81,$H$44,0)))))) -> 46510 | C33: =C32-D32 -> 15888889 | D33: =IF(C33=0,L33,IF(C33>1,I33)) -> 1444444.4 | E33: =IF(C33=0,N32,IF(C33>1,L33)) -> 835799.04 | F33: =IF(C33=0,N32,IF(C33>1,M33)) -> 2280243.5 | G33: =B33-B32 -> 32 | H33: =DATE(YEAR(B33),12,31)-DATE(YEAR(B33),1,1)+1 -> 365 | I33: =IF($L$5=A33,K33,IF($L$5>A33,I32)) -> 1444444.4 | J33: =SUM($I$8:I32) -> 36111111 | K33: =$J$12-J33 -> 15888889 | L33: =ROUND(C33*malumot!$B$84/H33,2)*G33 -> 835799.04 | M33: =D33+E33 -> 2280243.5 | O33: =TEXT(R33,"ддд") -> Сб | P33: =IF(O33=$U$8,2,IF(O33=$V$8,1,0)) -> 2 | Q33: =DAY(malumot!$B$78)+P33 -> 3 | R33: =IF(A33<=malumot!$B$81,DATE(YEAR($B$8),MONTH($B$8)+A32,DAY(malumot!$B$78)),0) -> 46508
A34: =1+A33 -> 27 | B34: =IF(A34<=malumot!$B$81,DATE(YEAR(R34),MONTH(R34),DAY(IF(A34=malumot!$B$81,malumot!$B$67,IF(A34<malumot!$B$81,(Q34),IF(A34>malumot!$B$81,$H$44,0)))))) -> 46539 | C34: =C33-D33 -> 14444445 | D34: =IF(C34=0,L34,IF(C34>1,I34)) -> 1444444.4 | E34: =IF(C34=0,N33,IF(C34>1,L34)) -> 688584.41 | F34: =IF(C34=0,N33,IF(C34>1,M34)) -> 2133028.9 | G34: =B34-B33 -> 29 | H34: =DATE(YEAR(B34),12,31)-DATE(YEAR(B34),1,1)+1 -> 365 | I34: =IF($L$5=A34,K34,IF($L$5>A34,I33)) -> 1444444.4 | J34: =SUM($I$8:I33) -> 37555555 | K34: =$J$12-J34 -> 14444445 | L34: =ROUND(C34*malumot!$B$84/H34,2)*G34 -> 688584.41 | M34: =D34+E34 -> 2133028.9 | O34: =TEXT(R34,"ддд") -> Вт | P34: =IF(O34=$U$8,2,IF(O34=$V$8,1,0)) -> 0 | Q34: =DAY(malumot!$B$78)+P34 -> 1 | R34: =IF(A34<=malumot!$B$81,DATE(YEAR($B$8),MONTH($B$8)+A33,DAY(malumot!$B$78)),0) -> 46539
A35: =1+A34 -> 28 | B35: =IF(A35<=malumot!$B$81,DATE(YEAR(R35),MONTH(R35),DAY(IF(A35=malumot!$B$81,malumot!$B$67,IF(A35<malumot!$B$81,(Q35),IF(A35>malumot!$B$81,$H$44,0)))))) -> 46569 | C35: =C34-D34 -> 13000000 | D35: =IF(C35=0,L35,IF(C35>1,I35)) -> 1444444.4 | E35: =IF(C35=0,N34,IF(C35>1,L35)) -> 641095.8 | F35: =IF(C35=0,N34,IF(C35>1,M35)) -> 2085540.2 | G35: =B35-B34 -> 30 | H35: =DATE(YEAR(B35),12,31)-DATE(YEAR(B35),1,1)+1 -> 365 | I35: =IF($L$5=A35,K35,IF($L$5>A35,I34)) -> 1444444.4 | J35: =SUM($I$8:I34) -> 39000000 | K35: =$J$12-J35 -> 13000000 | L35: =ROUND(C35*malumot!$B$84/H35,2)*G35 -> 641095.8 | M35: =D35+E35 -> 2085540.2 | O35: =TEXT(R35,"ддд") -> Чт | P35: =IF(O35=$U$8,2,IF(O35=$V$8,1,0)) -> 0 | Q35: =DAY(malumot!$B$78)+P35 -> 1 | R35: =IF(A35<=malumot!$B$81,DATE(YEAR($B$8),MONTH($B$8)+A34,DAY(malumot!$B$78)),0) -> 46569
