Workbook
Name mos: '[1]Общие данные'!$C$23:$D$23
Name mulk: '[1]Общие данные'!$C$24:$W$24

Sheet malumot
A1: =CONCATENATE(B65," olish uchun ariza") -> mikroqarz olish uchun ariza | B1: №745-SM
A2: =CONCATENATE(B65," olish uchun ariza sanasi QO’L BILAN KIRITILADI") -> mikroqarz olish uchun ariza sanasi QO’L BILAN KIRITILADI | B2: 10.04.2025 | D2: =180+B2 -> 45937
A4: Qarz oluvchi bo’yicha ma’lumotlar
A5: Ariza beruvchining FISh (kim? – Ibragimov Rustam Sadikovich) | B5: DJURAKULOVA SANAM ASHUROVNA | C5: yu
A6: agar o’zgarishlar bo’lgan bo’lsa oldingi FISh (Sadikov Rustam Sadikovich yoki yo’q) | B6: yo’q | C6: ha | D6: yo’q
A7: Ariza beruvchining FISh (kim? – Ibragimov R.S.) | B7: DJURAKULOVA S.A.
A8: FISh (ariza kimdan? – Ibragimov Rustam Sadikovichdan) | B8: =B5 -> DJURAKULOVA SANAM ASHUROVNA
A9: FISh (kimdan? – Ibragimov R.S.dan) | B9: =B7 -> DJURAKULOVA S.A.
A10: FISh (kimga? – Ibragimov Rustam Sadikovichga) | B10: =B8 -> DJURAKULOVA SANAM ASHUROVNA
A11: FISh (kimga? – Ibragimov R.S.ga) | B11: =B9 -> DJURAKULOVA S.A.
A12: FISh (kim bilan? – Ibragimov Rustam Sadikovich bilan) | B12: =B10 -> DJURAKULOVA SANAM ASHUROVNA
A13: FISh (kim bilan? – Ibragimov R.S. bilan) | B13: =B11 -> DJURAKULOVA S.A.
A14: Fuqaroligi (O’zbekiston Respublikasi) | B14: O’zbekiston Respublikasi
A15: Tug’ilgan sanasi (01.10.2011 yil) | B15: 18.07.1970 y
A16: Pasport seriyasi (СА №1234567) | B16: AB 0252157
B17: SAMARQAND VILOYATI SAMARQAND SHAHAR IIB | D17: =TEXT(C17,"ДД.ММ.ГГГГ") -> 00.01.1900
B18: 42184 | C18: =TEXT(B18,"ДД.ММ.ГГГГ") -> 29.06.2015
B19: =DATE(YEAR(B18)+10,MONTH(B18),DAY(B18)-1) -> 45836 | C19: =TEXT(B19,"ДД.ММ.ГГГГ") -> 28.06.2025
A20: Kim va qachon berilgan (Toshkent shahri Chilonzor IIB tomonidan 2011 yil __.____) | B20: =""&B17&" tomonidan "&C18&" yilda berilgan" -> SAMARQAND VILOYATI SAMARQAND SHAHAR IIB tomonidan 29.06.2015 yilda berilgan | C20: =""&B17&" tomonidan "&C18&" yilda berilgan" -> SAMARQAND VILOYATI SAMARQAND SHAHAR IIB tomonidan 29.06.2015 yilda berilgan
A21: Pasportni amal qilish muddati (01.10.2011 yilgacha / yoki muddatsiz) | B21: =""&C19&" y." -> 28.06.2025 y. | C21: =""&C19&" yilgacha" -> 28.06.2025 yilgacha
A22: doimiy ro’yhatdan o’tgan joyi (Toshkent sh., Mirobod tumani, Nukus ko’chasi, 1 uy, 1 honadon) | B22: SAMARQAND VILOYATI SAMARQAND SHAHAR BOG'ISARIY MAHALLASI SPITAMENSHOX KO'CHASI 252 UY | C22: =TEXT(B19,"ДД.ММ.ГГГГ") -> 28.06.2025
A23: doimiy ro’yhatdan o’tgan joyi haqiqatdagi turar joyi bilan mos keladi/mos kelmaydi | B23: mos keladi | C23: mos keladi | D23: mos kelmaydi
A24: Ro’yhatdan o’tish joyida yashash asosi | B24: Mulk huquqi | C24: Mulk huquqi | D24: ijara | E24: служебная | F24: другое | G24: -
A25: Telefon raqami kod bilan ((99871) 277 77 77) | B25: 90 606-09-53 UZI
A26: Mo’ljal | B26: SUPER XOTDOG. PED INSTITUTDAN O'TGANDA KOICAGA YETMASDAN
B27: =IF(B23="mos keladi",B22,B28) -> SAMARQAND VILOYATI SAMARQAND SHAHAR BOG'ISARIY MAHALLASI SPITAMENSHOX KO'CHASI 252 UY
A28: Haqiqatdagi yashash joyi (Toshkent sh., Mirobod tumani, Nukus ko’chasi, 1 uy, 1 honadon) | B28: SAMARQAND VILOYATI SAMARQAND SHAHAR BOG'ISARIY MAHALLASI SPITAMENSHOX KO'CHASI 252 UY
A29: Haqiqatdagi yashash joyida turish asosi | B29: Mulk huquqi | C29: Mulk huquqi | D29: ijara | E29: xizmat | F29: boshqa | G29: -
A30: Mijozning jinsi | B30: ayol | C30: erkak | D30: ayol
A31: Tug’ilgan joyi (Toshkent) | B31: SAMARQAND SHAHRI | C31: i
A32: Fuqaroligi (O’zbekiston Respublikasi) | B32: O’zbekiston Respublikasi
A33: Telefon raqami kod bilan ((99871) 277 77 77) | B33: 90 606-09-53 UZI
B34: =IF(B23="mos keladi",B26,B35) -> SUPER XOTDOG. PED INSTITUTDAN O'TGANDA KOICAGA YETMASDAN
A35: Mo’ljal
A36: Oilaviy ahvoli
A37: Oila a'zolari soni (jami):
A38: Ma’lumoti
A39: Mutaxassisligi | B39: {=+A39:B102} -> Mutaxassisligi
A40: Ish telefoni raqami kod bilan ((99890) 3270000) | B40: =B25 -> 90 606-09-53 UZI
A41: Mobil telefon raqami kod bilan ((99890) 3270000) | B41: 90 504-18-38 JASUR JIYANI
...

Sheet shartnoma
A1: =""&malumot!C64&" shartnoma "&malumot!B66&"" -> Mikroqarz shartnoma №745-SM
A3: ="Toshkent shahri "&malumot!B70&"" -> Toshkent shahri 10 aprel 2025 y.
A5: =""&malumot!B155&", bundan buyon «Mikromoliya tashkiloti» deb nomlanuvchi, ishonchnoma asosida xarakat qiluvchi "&malumot!A158&" "&malumot!B158&" bir tomondan va o‘z manfaati yo‘lida hamda o‘z nomidan harakat qiluvchi O‘zbekiston Respublikasi fuqarosi "&malumot!B5&" (pasport raqami "&malumot!B16&", "&malumot!C20&" ), bundan buyon «Qarz oluvchi» deb nomlanuvchi, boshqa tomondan, birgalikda “Tomonlar” yoki alohida “Tomon” deb nomlanuvchilar, Qarz oluvchi tomonidan "&TEXT(malumot!B2,"ДД.ММ.ГГГГ")&" yil,"&malumot!B65&" olish uchun ariza berilganligini hisobga olib, ushbu "&malumot!C64&" shartnomasini (bundan keyin – «Shartnoma») quyidagilar haqida tuzdilar:" -> «CLEVER MIKROMOLIYA TASHKILOTI» MChJ, bundan buyon «Mikromoliya tashkiloti» deb nomlanuvchi, ishonchnoma asosida xarakat qiluvchi Samarqand filiali boshlig'i S.Asrorov bir tomondan va o‘z manfaati yo‘lida hamda o‘z nomidan harakat qiluvchi O‘zbekiston Respublikasi fuqarosi DJURAKULOVA SANAM ASHUROVNA (pasport raqami AB 0252157, SAMARQAND VILOYATI SAMARQAND SHAHAR IIB tomonidan 29.06.2015 yilda berilgan ), bundan buyon «Qarz oluvchi» deb nomlanuvchi, boshqa tomondan, birgalikda “Tomonlar” yoki alohida “Tomon” deb nomlanuvchilar, Qarz oluvchi tomonidan 10.04.2025 yil,mikroqarz olish uchun ariza berilganligini hisobga olib, ushbu Mikroqarz shartnomasini (bundan keyin – «Shartnoma») quyidagilar haqida tuzdilar:
A7: 1. SHARTNOMA PREDMETI
A8: ="1.1. Mikromoliya tashkiloti Qarz oluvchiga umumiy miqdori "&FIXED(malumot!B75,2)&" ("&malumot!C76&") bo‘lgan "&malumot!B65&"ni "&malumot!B71&" dan "&malumot!B73&" gacha bo'lgan muddatga naqd pul va/yoki o'tkazmasi shaklida ajratadi." -> 1.1. Mikromoliya tashkiloti Qarz oluvchiga umumiy miqdori 40 000 000,00 (Qirq million so'm) bo‘lgan mikroqarzni 10 aprel 2025 y. dan 10 aprel 2027 y. gacha bo'lgan muddatga naqd pul va/yoki o'tkazmasi shaklida ajratadi.
A9: ="1.2. Qarz oluvchi to‘lovlilik, muddatlilik va ta’minlanganlik tamoyillariga amal qilgan holda "&malumot!B65&"dan foydalanish majburiyatini o‘z zimmasiga oladi." -> 1.2. Qarz oluvchi to‘lovlilik, muddatlilik va ta’minlanganlik tamoyillariga amal qilgan holda mikroqarzdan foydalanish majburiyatini o‘z zimmasiga oladi.
A11: ="2. "&malumot!D64&" BERISH VA QAYTARISH TARTIBI" -> 2. MIKROQARZ BERISH VA QAYTARISH TARTIBI
A12: ="2.1. Ushbu Shartnomaning 1.1.-bandida ko‘rsatilgan summa miqdoridagi "&malumot!B65&" Mikromoliya tashkiloti kassasidan naqd pul shaklida va/yoki plastik kartaga o‘tkazish yuli bilan beriladi." -> 2.1. Ushbu Shartnomaning 1.1.-bandida ko‘rsatilgan summa miqdoridagi mikroqarz Mikromoliya tashkiloti kassasidan naqd pul shaklida va/yoki plastik kartaga o‘tkazish yuli bilan beriladi.
A13: ="2.2. "&malumot!C64&" berish ushbu Shartnoma tuzilgan va Qarz oluvchi tomonidan ushbu shartnomaning 3-bo‘limiga muvofiq garov ta'minoti ta'minlangandan so‘ng 10 kalendar kundan kechiktirmay amalga oshiriladi." -> 2.2. Mikroqarz berish ushbu Shartnoma tuzilgan va Qarz oluvchi tomonidan ushbu shartnomaning 3-bo‘limiga muvofiq garov ta'minoti ta'minlangandan so‘ng 10 kalendar kundan kechiktirmay amalga oshiriladi.
A14: ="2.3. "&malumot!C64&" Qarz oluvchi tomonidan ushbu Shartnomaning ajralmas qismi hisoblanadigan 1-ilovasida ko‘rsatilgan to‘lov jadvalida (bundan keyin - To‘lov jadvali) belgilangan miqdor, tartib va muddatlarda qaytariladi." -> 2.3. Mikroqarz Qarz oluvchi tomonidan ushbu Shartnomaning ajralmas qismi hisoblanadigan 1-ilovasida ko‘rsatilgan to‘lov jadvalida (bundan keyin - To‘lov jadvali) belgilangan miqdor, tartib va muddatlarda qaytariladi.
A15: ="2.4. Mikromoliya tashkiloti, "&malumot!B65&" berilgan vaqtdan boshlab, "&malumot!B65&" miqdorining qoldiq summasiga "&malumot!B85&"% ("&malumot!C86&") foiz yillik va yiliga 365/366 kunlik hisobidan foizlar hisoblaydi. To'lov jadvaliga muvofiq asosiy qarz bo'yicha navbatdagi to'lov buzilgan hollarda, "&"foiz stavkasi oshiriladi va Mikromoliya tashkiloti "&malumot!B65&"ning muddati o'tgan asosiy qarz summasiga yillik "&malumot!B88&" ("&malumot!B89&") foiz miqdorida foizlar hisoblaydi." -> 2.4. Mikromoliya tashkiloti, mikroqarz berilgan vaqtdan boshlab, mikroqarz miqdorining qoldiq summasiga 55% (Ellik besh ) foiz yillik va yiliga 365/366 kunlik hisobidan foizlar hisoblaydi. To'lov jadvaliga muvofiq asosiy qarz bo'yicha navbatdagi to'lov buzilgan hollarda, foiz stavkasi oshiriladi va Mikromoliya tashkiloti mikroqarzning muddati o'tgan asosiy qarz summasiga yillik 105 (bir yuz besh) foiz miqdorida foizlar hisoblaydi.
A16: 2.4.1 Qarz oluvchining xisob raqamlaridan shartnomaning 4.1.2 bandida ko‘rsatilgan tartibda yechib olingan pul mablag‘lari yechib olinganidan so‘ng mijoz tomonidan kredit qarzdorligini so‘ndirish uchun bank kassalari orqali to‘langan pul mablag‘lari yoki mijoz tomonidan kredit qarzdorligini so‘ndirish uchun bank kassalari orqali to‘langandan so‘ng qarz oluvchining xisob raqamlaridan shartnomaning 4.1.2 bandida ko‘rsatilgan tartibda yechib olingan pul mablag‘larining bir oylik kredit to‘lovini so‘ndirishga yo‘naltirilgan miqdoridan ortiqcha qismi qarz oluvchining to‘lov amalga oshirilgan kundan boshlab 3 bank ish kuni ichida yo‘llagan arizasiga asosan qarz oluvchiga qaytarilishi mumkun. 2.5. Foizlar To‘lov jadvaliga muvofiq asosiy qarzni qaytarish uchun belgilangan sanada to‘lanadi. 2.5.1 Qarz oluvchi tomonidan shartnomaning 2.4 bandida ko‘rsatilgan muddatda ortiqcha to‘langan pul mablag‘larini qaytarish to‘g‘risida ariza berilmagan taqdirda to‘langan ortiqcha pul mablag‘lari mijozning asosiy qarzdorligini so‘ndirishga yo‘naltiriladi.
A17: =CONCATENATE(C17,H17,I17) -> 2.6 Qarz oluvchi tomonidan to‘lov jadvalida ko‘rsatilgan muddatdan oldin xamda to‘lov jadvalida ko‘rsatilgan oylik kredit qarzdorligini so‘ndirish miqdoridan ko‘p miqdorda to‘lovni amalga oshirib, to‘langan pul mablag‘larini asosiy kredit qarzdorligini so‘ndirishga yo‘naltirilishini so‘ralganda qarz oluvchining kredit qarzdorligini so‘ndirish uchun to‘lagan pul mablag‘laridan kredit qarzdorligi to‘langan oy uchun to‘lov jadvali bo‘yicha so‘ndirilishi lozim bo‘lgan foiz qarzdorligi summasi, to‘lov jadvalida foiz qarzdorligi so‘ndirilishi ko‘rsatilgan muddatga qadar tashkilotning xisob raqamida saqlanib to‘lov jadvalida ko‘rsatilgan sanada oylik foiz qarzdorligini so‘ndirishga yo‘naltiriladi. 2.6.1. Qarz oluvchi tomonidan olingan mikroqarzni va undan foydalanganlik uchun foizlarni qaytarish bo‘yicha muddati o‘tgan qarzdorlik hosil bo‘lganda Qarz oluvchi tomonidan ko‘rsatilgan qarzdorlikni to‘lash hisobiga to‘lanadigan summalar quyidagi tartibda hisobga olinadi: | C17: 2.6 Qarz oluvchi tomonidan to‘lov jadvalida ko‘rsatilgan muddatdan oldin xamda to‘lov jadvalida ko‘rsatilgan oylik kredit qarzdorligini so‘ndirish miqdoridan ko‘p miqdorda to‘lovni amalga oshirib, to‘langan pul mablag‘larini asosiy kredit qarzdorligini so‘ndirishga yo‘naltirilishini so‘ralganda qarz oluvchining kredit qarzdorligini so‘ndirish uchun to‘lagan pul mablag‘laridan kredit qarzdorligi to‘langan oy uchun to‘lov jadvali bo‘yicha so‘ndirilishi lozim bo‘lgan foiz qarzdorligi summasi, to‘lov jadvalida foiz qarzdorligi so‘ndirilishi ko‘rsatilgan muddatga qadar tashkilotning xisob raqamida saqlanib to‘lov jadvalida ko‘rsatilgan sanada oylik foiz qarzdorligini so‘ndirishga yo‘naltiriladi. 2.6.1. Qarz oluvchi tomonidan olingan | H17: =malumot!B65 -> mikroqarz | I17: ni va undan foydalanganlik uchun foizlarni qaytarish bo‘yicha muddati o‘tgan qarzdorlik hosil bo‘lganda Qarz oluvchi tomonidan ko‘rsatilgan qarzdorlikni to‘lash hisobiga to‘lanadigan summalar quyidagi tartibda hisobga olinadi:
A18: - jarima sanksiyalarni to‘lash; - to‘lov muddati o‘tgan foizlarni to‘lash; - to‘lov muddati o‘tgan asosiy qarzni to‘lash; - muddatli qarz bo‘yicha hisoblangan foizlarni to‘lash; - muddatli asosiy qarzni to‘lash; - Mikromoliya tashkilotning boshqa zararlarini qoplash.
A19: ="2.7. Qarz oluvchi Mikromoliya tashkilotining "&malumot!B65&" bo‘yicha asosiy summasi, hisoblangan foizlarni, penya va boshqa moliyaviy talablarini ham naqd pul shaklida, ham naqdsiz shaklda qaytarib beradi." -> 2.7. Qarz oluvchi Mikromoliya tashkilotining mikroqarz bo‘yicha asosiy summasi, hisoblangan foizlarni, penya va boshqa moliyaviy talablarini ham naqd pul shaklida, ham naqdsiz shaklda qaytarib beradi.
A20: ="2.8. Qarz oluvchi "&malumot!B65&" miqdorini muddatidan oldin qaytarish, shuningdek, bu haqida Mikromoliya tashkilotini albatta ogohlantirgan holda ulardan aniq foydalangan muddat uchun hisoblangan foizlarni to‘lash huquqiga ega." -> 2.8. Qarz oluvchi mikroqarz miqdorini muddatidan oldin qaytarish, shuningdek, bu haqida Mikromoliya tashkilotini albatta ogohlantirgan holda ulardan aniq foydalangan muddat uchun hisoblangan foizlarni to‘lash huquqiga ega.
A21: =CONCATENATE(C21,H21,I21) -> 2.9. Qarz oluvchi jismoniy shaxslarning kreditlar (mikroqarzlar) bo‘yicha qarz yukini hisoblash tartibi, qarz yukining ruxsat etilgan miqdori, shuningdek qarz yuki o‘sishini cheklash to‘g‘risidagi Nizomga muvofiq (O’zbekiston Respublikasi Adliya vazirligi tomonidan 19.12.2019 y. 3205-son bilan ro‘yxatga olingan Markaziy bank Boshqaruvining 28.09.2019 y. 24/5-son qarori bilan tasdiqlangan), qarz yuki ko‘rsatkichi har bir qarz oluvchiga qarz beruvchi tomonidan mikroqarz ajratishda uning summasi va qarz oluvchining amaldagi kredit (mikroqarz) shartnomalari bo‘yicha asosiy qarz qoldig‘i yig‘indisi bazaviy hisoblash miqdorining 50 baravaridan oshganda hisoblanadi. | C21: ="2.9. Qarz oluvchi jismoniy shaxslarning kreditlar ("&malumot!B65&"lar) bo‘yicha qarz yukini hisoblash tartibi, qarz yukining ruxsat etilgan miqdori, shuningdek qarz yuki o‘sishini cheklash to‘g‘risidagi Nizomga muvofiq (O’zbekiston Respublikasi Adliya vazirligi tomonidan 19.12.2019 y. 3205-son bilan ro‘yxatga " -> 2.9. Qarz oluvchi jismoniy shaxslarning kreditlar (mikroqarzlar) bo‘yicha qarz yukini hisoblash tartibi, qarz yukining ruxsat etilgan miqdori, shuningdek qarz yuki o‘sishini cheklash to‘g‘risidagi Nizomga muvofiq (O’zbekiston Respublikasi Adliya vazirligi tomonidan 19.12.2019 y. 3205-son bilan ro‘yxatga | H21: ="olingan Markaziy bank Boshqaruvining 28.09.2019 y. 24/5-son qarori bilan tasdiqlangan), qarz yuki ko‘rsatkichi har bir qarz oluvchiga qarz beruvchi tomonidan "&malumot!B65&" ajratishda uning summasi va " -> olingan Markaziy bank Boshqaruvining 28.09.2019 y. 24/5-son qarori bilan tasdiqlangan), qarz yuki ko‘rsatkichi har bir qarz oluvchiga qarz beruvchi tomonidan mikroqarz ajratishda uning summasi va | I21: ="qarz oluvchining amaldagi kredit ("&malumot!B65&") shartnomalari bo‘yicha asosiy qarz qoldig‘i yig‘indisi bazaviy hisoblash miqdorining 50 baravaridan oshganda hisoblanadi." -> qarz oluvchining amaldagi kredit (mikroqarz) shartnomalari bo‘yicha asosiy qarz qoldig‘i yig‘indisi bazaviy hisoblash miqdorining 50 baravaridan oshganda hisoblanadi.
A22: ="3. "&malumot!D64&" TA'MINOTI BO‘YICHA " -> 3. MIKROQARZ TA'MINOTI BO‘YICHA
A23: ="3.1. Ushbu Shartnoma bo‘yicha taqdim etilgan "&malumot!C64&" quyidagi garov bilan ta'minlanadi:" -> 3.1. Ushbu Shartnoma bo‘yicha taqdim etilgan Mikroqarz quyidagi garov bilan ta'minlanadi:
A24: =IF(malumot!B111=malumot!C111,shartnoma!A28,IF(malumot!B111=malumot!D111,shartnoma!A25,0)) -> 3.1.1. Mikromoliya tashkiloti va Qarz oluvchi tomonidan 2025 yil 10 aprelda imzolangan 1-sonli garov predmeti qiymatini tasdiqlash dalolatnomasiga muvofiq QORA CHERNIY rangli, ishlab chiqarilgan yili – 2011 yil, dvigatel raqami 2132251, shassi - RAKAMSIZ, kuzov turi - YENGIL SEDAN, kuzov raqami №XWB5M31BDBA256320 TASH KUR GENTRA, davlat raqam belgisi 30O259OA bo'lgan LACETTI rusumli avtomashinasi (bundan keyin “Garov predmeti”), egalik huquqiga ega DJURAKULOVA S.A.ga tegishli va kelishilgan garov qiymati 2025 yil 10 aprelda imzolangan 1-sonli Garov predmeti qiymatini tasdiqlash dalolatnomasiga muvifiq 56 000 000,00 (ellik olti million so'm) so'mni tashkil qiladi. Garov garovining aniq shartlari tegishli notarial rasmiylashtirilgan garov shartnomasi bilan belgilanadi.
A25: =IF(malumot!B98=malumot!C98,shartnoma!A27,IF(malumot!B98=malumot!D98,shartnoma!A26,0)) -> 3.1.1. Mikromoliya tashkiloti va Qarz oluvchi tomonidan 2025 yil 10 aprelda imzolangan 1-sonli Garov predmeti qiymatini tasdiqlash dalolatnomasiga muvofiq SAMARQAND VILOYATI TAYLOQ TUMANI CHAROG'BON MFY YANGI TAYLOQ QISHLOG'I 6 TURAR JOY 12 QAVAT 58 XONADON manzilida joylashgan, yer uchastkasi maydoni - , umumiy maydoni - 72,13, yashash maydoni - 37,39 bo'lgan, 3 - xonali yakka tartibdagi uy-joy ko'rinishidagi ko'chmas mulk (bundan keyin “Garov predmeti”), egalik huquqiga ko'ra DJURAKULOVA SANAM ASHUROVNAga tegishli va kelishilgan garov qiymati 2025 yil 10 aprelda imzolangan 1-sonli Garov predmeti qiymatini tasdiqlash dalolatnomasiga muvofiq 56 000 000,00 (ellik olti million so'm) so'mni tashkil qiladi. Garovning aniq shartlari tegishli tarzda notarial tasdiqlangan garov shartnomasi bilan belgilangan.
A26: ="3.1.1. "&malumot!N134&" tomonidan "&malumot!B151&" yil "&malumot!B153&" "&malumot!B152&"da imzolangan 1-sonli navbatdagi garov predmeti qiymatini tasdiqlash dalolatnomasiga muvofiq "&malumot!C131&" manzilida joylashgan, "&malumot!E134&" bo'lgan, "&malumot!E133&" ko'rinishidagi ko'chmas mulk (bundan keyin “navbatdagi garov predmeti”), egalik huquqiga ko'ra "&malumot!C125&"ga tegishli va kelishilgan garov qiymati "&malumot!B151&" yil "&malumot!B153&" "&malumot!B152&"da imzolangan 1-sonli Garov predmeti qiymatini tasdiqlash dalolatnomasiga muvofiq "&FIXED(malumot!B144,2)&" ("&malumot!B146&") so'mni tashkil qiladi. Garovning aniq shartlari tegishli tarzda notarial tasdiqlangan garov shartnomasi bilan belgilangan." -> 3.1.1. Mikromoliya tashkiloti va Qarz oluvchi tomonidan 2025 yil 10 aprelda imzolangan 1-sonli navbatdagi garov predmeti qiymatini tasdiqlash dalolatnomasiga muvofiq SAMARQAND VILOYATI TAYLOQ TUMANI CHAROG'BON MFY YANGI TAYLOQ QISHLOG'I 6 TURAR JOY 12 QAVAT 58 XONADON manzilida joylashgan, yer uchastkasi maydoni - , umumiy maydoni - 72,13, yashash maydoni - 37,39 bo'lgan, 3 - xonali yakka tartibdagi uy-joy ko'rinishidagi ko'chmas mulk (bundan keyin “navbatdagi garov predmeti”), egalik huquqiga ko'ra DJURAKULOVA SANAM ASHUROVNAga tegishli va kelishilgan garov qiymati 2025 yil 10 aprelda imzolangan 1-sonli Garov predmeti qiymatini tasdiqlash dalolatnomasiga muvofiq 56 000 000,00 (ellik olti million so'm) so'mni tashkil qiladi. Garovning aniq shartlari tegishli tarzda notarial tasdiqlangan garov shartnomasi bilan belgilangan.
A27: ="3.1.1. "&malumot!N134&" tomonidan "&malumot!B151&" yil "&malumot!B153&" "&malumot!B152&"da imzolangan 1-sonli Garov predmeti qiymatini tasdiqlash dalolatnomasiga muvofiq "&malumot!C131&" manzilida joylashgan, "&malumot!E134&" bo'lgan, "&malumot!E133&" ko'rinishidagi ko'chmas mulk (bundan keyin “Garov predmeti”), egalik huquqiga ko'ra "&malumot!C125&"ga tegishli va kelishilgan garov qiymati "&malumot!B151&" yil "&malumot!B153&" "&malumot!B152&"da imzolangan 1-sonli Garov predmeti qiymatini tasdiqlash dalolatnomasiga muvofiq "&FIXED(malumot!B144,2)&" ("&malumot!B146&") so'mni tashkil qiladi. Garovning aniq shartlari tegishli tarzda notarial tasdiqlangan garov shartnomasi bilan belgilangan." -> 3.1.1. Mikromoliya tashkiloti va Qarz oluvchi tomonidan 2025 yil 10 aprelda imzolangan 1-sonli Garov predmeti qiymatini tasdiqlash dalolatnomasiga muvofiq SAMARQAND VILOYATI TAYLOQ TUMANI CHAROG'BON MFY YANGI TAYLOQ QISHLOG'I 6 TURAR JOY 12 QAVAT 58 XONADON manzilida joylashgan, yer uchastkasi maydoni - , umumiy maydoni - 72,13, yashash maydoni - 37,39 bo'lgan, 3 - xonali yakka tartibdagi uy-joy ko'rinishidagi ko'chmas mulk (bundan keyin “Garov predmeti”), egalik huquqiga ko'ra DJURAKULOVA SANAM ASHUROVNAga tegishli va kelishilgan garov qiymati 2025 yil 10 aprelda imzolangan 1-sonli Garov predmeti qiymatini tasdiqlash dalolatnomasiga muvofiq 56 000 000,00 (ellik olti million so'm) so'mni tashkil qiladi. Garovning aniq shartlari tegishli tarzda notarial tasdiqlangan garov shartnomasi bilan belgilangan.
A28: =IF(malumot!B98=malumot!C98,A29,IF(malumot!B98=malumot!D98,A30,0)) -> 3.1.1. Mikromoliya tashkiloti va Qarz oluvchi tomonidan 2025 yil 10 aprelda imzolangan 1-sonli garov predmeti qiymatini tasdiqlash dalolatnomasiga muvofiq QORA CHERNIY rangli, ishlab chiqarilgan yili – 2011 yil, dvigatel raqami 2132251, shassi - RAKAMSIZ, kuzov turi - YENGIL SEDAN, kuzov raqami №XWB5M31BDBA256320 TASH KUR GENTRA, davlat raqam belgisi 30O259OA bo'lgan LACETTI rusumli avtomashinasi (bundan keyin “Garov predmeti”), egalik huquqiga ega DJURAKULOVA S.A.ga tegishli va kelishilgan garov qiymati 2025 yil 10 aprelda imzolangan 1-sonli Garov predmeti qiymatini tasdiqlash dalolatnomasiga muvifiq 56 000 000,00 (ellik olti million so'm) so'mni tashkil qiladi. Garov garovining aniq shartlari tegishli notarial rasmiylashtirilgan garov shartnomasi bilan belgilanadi.
A29: ="3.1.1. "&malumot!N134&" tomonidan "&malumot!B151&" yil "&malumot!B153&" "&malumot!B152&"da imzolangan 1-sonli garov predmeti qiymatini tasdiqlash dalolatnomasiga muvofiq "&malumot!B142&" rangli, ishlab chiqarilgan yili – "&malumot!B143&" yil, dvigatel raqami "&malumot!B139&", shassi - "&malumot!B140&", kuzov turi - "&malumot!B136&", kuzov raqami №"&malumot!B137&", davlat raqam belgisi "&malumot!B134&" bo'lgan "&malumot!B133&" rusumli avtomashinasi (bundan keyin “Garov predmeti”), egalik huquqiga ega "&malumot!B125&"ga tegishli va kelishilgan garov qiymati "&malumot!B151&" yil "&malumot!B153&" "&malumot!B152&"da imzolangan 1-sonli Garov predmeti qiymatini tasdiqlash dalolatnomasiga muvifiq "&FIXED(malumot!B144,2)&" ("&malumot!B146&") so'mni tashkil qiladi. Garov garovining aniq shartlari tegishli notarial rasmiylashtirilgan garov shartnomasi bilan belgilanadi." -> 3.1.1. Mikromoliya tashkiloti va Qarz oluvchi tomonidan 2025 yil 10 aprelda imzolangan 1-sonli garov predmeti qiymatini tasdiqlash dalolatnomasiga muvofiq QORA CHERNIY rangli, ishlab chiqarilgan yili – 2011 yil, dvigatel raqami 2132251, shassi - RAKAMSIZ, kuzov turi - YENGIL SEDAN, kuzov raqami №XWB5M31BDBA256320 TASH KUR GENTRA, davlat raqam belgisi 30O259OA bo'lgan LACETTI rusumli avtomashinasi (bundan keyin “Garov predmeti”), egalik huquqiga ega DJURAKULOVA S.A.ga tegishli va kelishilgan garov qiymati 2025 yil 10 aprelda imzolangan 1-sonli Garov predmeti qiymatini tasdiqlash dalolatnomasiga muvifiq 56 000 000,00 (ellik olti million so'm) so'mni tashkil qiladi. Garov garovining aniq shartlari tegishli notarial rasmiylashtirilgan garov shartnomasi bilan belgilanadi.
A30: ="3.1.1. "&malumot!N134&" tomonidan "&malumot!B151&" yil "&malumot!B153&" "&malumot!B152&"da imzolangan 1-sonli navbatdagi garov predmeti qiymatini tasdiqlash dalolatnomasiga muvofiq "&malumot!B142&" rangli, ishlab chiqarilgan yili – "&malumot!B143&" yil, dvigatel raqami "&malumot!B139&", shassi - "&malumot!B140&", kuzov turi - "&malumot!B136&", kuzov raqami №"&malumot!B137&", davlat raqam belgisi "&malumot!B134&" bo'lgan "&malumot!B133&" rusumli avtomashinasi (bundan keyin “navbatdagi garov predmeti”), egalik huquqiga ega "&malumot!B125&"ga tegishli va kelishilgan garov qiymati "&malumot!B151&" yil "&malumot!B153&" "&malumot!B152&"da imzolangan 1-sonli Garov predmeti qiymatini tasdiqlash dalolatnomasiga muvifiq "&FIXED(malumot!B144,2)&" ("&malumot!B146&") so'mni tashkil qiladi. Garov garovining aniq shartlari tegishli notarial rasmiylashtirilgan garov shartnomasi bilan belgilanadi." -> 3.1.1. Mikromoliya tashkiloti va Qarz oluvchi tomonidan 2025 yil 10 aprelda imzolangan 1-sonli navbatdagi garov predmeti qiymatini tasdiqlash dalolatnomasiga muvofiq QORA CHERNIY rangli, ishlab chiqarilgan yili – 2011 yil, dvigatel raqami 2132251, shassi - RAKAMSIZ, kuzov turi - YENGIL SEDAN, kuzov raqami №XWB5M31BDBA256320 TASH KUR GENTRA, davlat raqam belgisi 30O259OA bo'lgan LACETTI rusumli avtomashinasi (bundan keyin “navbatdagi garov predmeti”), egalik huquqiga ega DJURAKULOVA S.A.ga tegishli va kelishilgan garov qiymati 2025 yil 10 aprelda imzolangan 1-sonli Garov predmeti qiymatini tasdiqlash dalolatnomasiga muvifiq 56 000 000,00 (ellik olti million so'm) so'mni tashkil qiladi. Garov garovining aniq shartlari tegishli notarial rasmiylashtirilgan garov shartnomasi bilan belgilanadi.
A31: =CONCATENATE(A32,B32) -> 3.2. Qonun hujjatlariga muvofiq rasmiylashtirilgan, “Garov predmeti” hisoblangan notarial tasdiqlangan garov shartnomasi, shu jumladan “Garov predmeti”ga taʼqiq quyilganligi tasdiqlovchi xujjat Qarz oluvchi tomonidan ushbu shartnoma tuzilgandan so‘ng 10 bank kuni mobaynida Mikromoliya tashkilotiga taqdim etilishi lozim. Garov shartnomasi belgilangan muddatda taqdim etilmagan hollarda, Mikromoliya tashkiloti Qarz oluvchining manziliga yozma bildirishnoma yuborish orqali mikroqarz berishni rad etish va / yoki ushbu shartnomani bir tomonlama bekor qilish huquqiga egadir. Bunda ushbu shartnoma Qarz oluvchi tomonidan talabnoma olingan vaqtda yoki talabnoma pochta xizmati orqali yuborilgandan keyin uchinchi kuni bekor qilingan hisoblanadi.
A32: 3.2. Qonun hujjatlariga muvofiq rasmiylashtirilgan, “Garov predmeti” hisoblangan notarial tasdiqlangan garov shartnomasi, shu jumladan “Garov predmeti”ga taʼqiq quyilganligi tasdiqlovchi xujjat Qarz oluvchi tomonidan ushbu shartnoma tuzilgandan so‘ng 10 bank kuni mobaynida | B32: =CONCATENATE(A33,B33) -> Mikromoliya tashkilotiga taqdim etilishi lozim. Garov shartnomasi belgilangan muddatda taqdim etilmagan hollarda, Mikromoliya tashkiloti Qarz oluvchining manziliga yozma bildirishnoma yuborish orqali mikroqarz berishni rad etish va / yoki ushbu shartnomani bir tomonlama bekor qilish huquqiga egadir. Bunda ushbu shartnoma Qarz oluvchi tomonidan talabnoma olingan vaqtda yoki talabnoma pochta xizmati orqali yuborilgandan keyin uchinchi kuni bekor qilingan hisoblanadi.
A33: =" Mikromoliya tashkilotiga taqdim etilishi lozim. Garov shartnomasi belgilangan muddatda taqdim etilmagan hollarda, Mikromoliya tashkiloti Qarz oluvchining manziliga yozma bildirishnoma yuborish orqali "&malumot!B65&"" -> Mikromoliya tashkilotiga taqdim etilishi lozim. Garov shartnomasi belgilangan muddatda taqdim etilmagan hollarda, Mikromoliya tashkiloti Qarz oluvchining manziliga yozma bildirishnoma yuborish orqali mikroqarz | B33: berishni rad etish va / yoki ushbu shartnomani bir tomonlama bekor qilish huquqiga egadir. Bunda ushbu shartnoma Qarz oluvchi tomonidan talabnoma olingan vaqtda yoki talabnoma pochta xizmati orqali yuborilgandan keyin uchinchi kuni bekor qilingan hisoblanadi.
A34: 3.3. Asosiy qarzni, foizlar yoki ushbu shartnoma bo‘yicha belgilangan muddatdan kechiktirilganligi bo‘yicha penyalarni qaytarish muddati kechiktirilishi yuzaga kelganda va/yoki ushbu shartnoma bo‘yicha boshqa majburiyatlar buzilishi holatlarida Mikromoliya tashkiloti O‘zbekiston Respublikasining amaldagi qonunchiligiga muvofiq qarzni undirish uchun qaytarib olinmaydigan va muqarrar tartibda unidirishni garov ob'ektiga qaratish huquqiga ega bo‘ladi.
A35: 3.4. O‘zbekiston Respublikasi "Garov to‘g‘risida" gi Qonunining 27-moddasiga muvofiq Garov predmeti sug‘urtalanmaydi. Lekin Mikromoliya tashkiloti Qarz oluvchidan Mikromoliya tashkiloti foydasiga Garov obʼektini ushbu Shartnomaning to‘liq amal qilish muddatiga har turli xavflardan sug‘urta qilishni talab qilish huquqiga ega. Bunda, sug‘urta xavflari ro‘yxati, shuningdek, sug‘urta kompaniyasi Mikromoliya tashkilotining xohishiga ko‘ra belgilanadi. Sug‘urta hodisasi yuz berganda Foyda oluvchi Mikromoliya tashkiloti bo‘lishi kerak.
A37: 4. MIKROMOLIYA TASHKILOTINING HUQUQ VA MAJBURIYATLARI
A38: 4.1. Mikromoliya tashkiloti quyidagi huquqlarga ega:
A39: =CONCATENATE(C39,H39) -> 4.1.1. Ushbu Shartnomada ko‘rsatilgan asoslar bo‘yicha Qarz oluvchiga Shartnomada ko‘zda tutilgan mikroqarz summasini berilishini to‘liq yoki qisman rad etish. 4.1.2 “Mikromoliya Tashkiloti” qarz oluvchining nomidagi barcha plastik kartalaridan, xozirgi kunda mavjud va bundan so‘ng ochiladigan barcha xisob raqamlaridan (talab qilib olguncha, depozit jamg‘arib boriladigan plastik va boshqa istalgan xisob raqamlaridan) kredit to‘lovini kredit qaytarish jadvaliga asosan oyning kredit qarzdorligi qaytarilishi ko‘rsatilgan kuni akseptsiz tarzda yechib olish xuquqiga ega.Usbu bandda belgilangan harakatlarni amalga oshirish uchun bo‘lgan barcha xarajatlar Qarz oluvchi xisobidan qoplanadi | C39: ="4.1.1. Ushbu Shartnomada ko‘rsatilgan asoslar bo‘yicha Qarz oluvchiga Shartnomada ko‘zda tutilgan "&malumot!B65&"" -> 4.1.1. Ushbu Shartnomada ko‘rsatilgan asoslar bo‘yicha Qarz oluvchiga Shartnomada ko‘zda tutilgan mikroqarz | H39: summasini berilishini to‘liq yoki qisman rad etish. 4.1.2 “Mikromoliya Tashkiloti” qarz oluvchining nomidagi barcha plastik kartalaridan, xozirgi kunda mavjud va bundan so‘ng ochiladigan barcha xisob raqamlaridan (talab qilib olguncha, depozit jamg‘arib boriladigan plastik va boshqa istalgan xisob raqamlaridan) kredit to‘lovini kredit qaytarish jadvaliga asosan oyning kredit qarzdorligi qaytarilishi ko‘rsatilgan kuni akseptsiz tarzda yechib olish xuquqiga ega.Usbu bandda belgilangan harakatlarni amalga oshirish uchun bo‘lgan barcha xarajatlar Qarz oluvchi xisobidan qoplanadi
A40: ="4.1.2.1. "&malumot!C64&" bo‘yicha qolgan barcha qarzdorlik, foiz to‘lovlarining muddatidan oldin qaytarilishini talab qilish, shuningdek, quyidagi holatlardan biri yuzaga kelganda undirishni garov ta'minotiga qaratish:" -> 4.1.2.1. Mikroqarz bo‘yicha qolgan barcha qarzdorlik, foiz to‘lovlarining muddatidan oldin qaytarilishini talab qilish, shuningdek, quyidagi holatlardan biri yuzaga kelganda undirishni garov ta'minotiga qaratish:
A41: a) ta'minotisiz qarzdorlik yuzaga kelganda;
A42: ="b) "&malumot!B65&" summasiga hisoblanadigan asosiy qarz bo‘yicha muddati o‘tgan qarzdorlik va/yoki foizlarning yuzaga kelishi;" -> b) mikroqarz summasiga hisoblanadigan asosiy qarz bo‘yicha muddati o‘tgan qarzdorlik va/yoki foizlarning yuzaga kelishi;
A43: с) Qarz oluvchini qonun hujjatlarida belgilangan tartibda to‘lov qobiliyatiga ega emas, muomalaga layoqatli emas yoki muomalaga layoqati cheklangan deb e'lon qilish;
A44: d) Mikromoliya tashkilotiga ushbu Shartnomaning 3.1.-bandida ko‘zda tutilgan hisobotlar, axborotlar va boshqa ma'lumotlarni o‘z vaqtida taqdim etmaslik, shuningdek, moliya-xo‘jalik faoliyat va daromad to‘g‘risidagi hisobotning ishonchsizligi holatlari aniqlanganda;
A45: e) Qarz oluvchi tomonidan ushbu shartnoma shartlariga amal qilmaslik;
...

Sheet buyruq
A4: =""&malumot!B155&" ijrochi direktorining "&malumot!B177&"dagi "&malumot!B172&"-sonli buyrug‘i" -> «CLEVER MIKROMOLIYA TASHKILOTI» MChJ ijrochi direktorining dagi №745-SM-sonli buyrug‘i
A8: ="Men, Abduraximov Nadirbek Kamilevich "&malumot!B155&" ijrochi direktori, jismoniy shaxs "&malumot!B10&"ga quyidagi shartlarda "&malumot!B65&" berishni buyuraman:" -> Men, Abduraximov Nadirbek Kamilevich «CLEVER MIKROMOLIYA TASHKILOTI» MChJ ijrochi direktori, jismoniy shaxs DJURAKULOVA SANAM ASHUROVNAga quyidagi shartlarda mikroqarz berishni buyuraman:
A9: =kredit_ariza!A13:D13 -> Mikroqarz summasi: 40 000 000,00 (qirq million so'm) so'm.
A10: =kredit_ariza!A14:D14 -> Mikroqarz muddati: 24 (Yigirma to'rt ) oy.
A11: =kredit_ariza!A15:D15 -> Mikroqarzdan foydalanganlik uchun foiz stavkasi: yillik 55% (Ellik besh ) foiz
A12: =kredit_ariza!A16:D16 -> Mikroqarz bo'yicha asosiy qarz va foizlarni to'lash:
A13: =kredit_ariza!A17:D17 -> - mikroqarz shartnomasi bo'yicha har oy differensial to'lovlari amalga oshiriladi
A14: =kredit_ariza!A19:D19 -> - mikroqarz shartnomasi bo'yicha har oy differensial to'lovlari amalga oshiriladi
A15: =IF(malumot!B111="Avtotransport",buyruq!A14:E14,buyruq!A13:E13) -> - mikroqarz shartnomasi bo'yicha har oy differensial to'lovlari amalga oshiriladi
A16: =IF(malumot!B111=malumot!D111,""&malumot!C125&"ga tegishli "&malumot!C134&" ko'rinishidagi ko'chmas mulkni quyidagi ma'lumotlarga muvofiq garovga qabul qilinsin:",""&malumot!B125&"ga tegishli "&malumot!B133&" ko'rinishidagi transport vositasini quyidagi ma'lumotlarga muvofiq garovga qabul qilinsin:") -> DJURAKULOVA S.A.ga tegishli LACETTI ko'rinishidagi transport vositasini quyidagi ma'lumotlarga muvofiq garovga qabul qilinsin:
A17: =""&malumot!C125&"ga tegishli "&malumot!C134&" ko'rinishidagi ko'chmas mulkni quyidagi ma'lumotlarga muvofiq garovga qabul qilinsin:" -> DJURAKULOVA SANAM ASHUROVNAga tegishli 3 - xonali yakka tartibdagi uy-joy ko'rinishidagi ko'chmas mulkni quyidagi ma'lumotlarga muvofiq garovga qabul qilinsin:
A18: =""&malumot!B125&"ga tegishli "&malumot!B133&" ko'rinishidagi transport vositasini quyidagi ma'lumotlarga muvofiq garovga qabul qilinsin:" -> DJURAKULOVA S.A.ga tegishli LACETTI ko'rinishidagi transport vositasini quyidagi ma'lumotlarga muvofiq garovga qabul qilinsin:
A19: =dalolatnoma!A29 -> Nomi | B19: =dalolatnoma!B29 -> Kuzov turi va kuzov raqami* | C19: =dalolatnoma!C29 -> Dvigatel va shassi raqami* | D19: =dalolatnoma!D29 -> Ishlab chiqarilgan yili va rangi* | E19: =dalolatnoma!E29 -> Kelishilgan garov qiymati, so'm
A20: =dalolatnoma!A30 -> LACETTI | B20: =dalolatnoma!B30 -> kuzov turi - YENGIL SEDAN, kuzov raqami XWB5M31BDBA256320 TASH KUR GENTRA | C20: =dalolatnoma!C30 -> dvigatel raqami 2132251, shassi raqami - RAKAMSIZ | D20: =dalolatnoma!D30 -> rangi - QORA CHERNIY, ishlab chiqarilgan yili - 2011 | E20: =dalolatnoma!E30 -> 56 000 000,00 (ellik olti million so'm)
A21: =dalolatnoma!A22:E22 -> -* avtotransport egasi: DJURAKULOVA S.A.
A22: =dalolatnoma!A23:E23 -> -* texnik pasport: AAG 4271140 05.07.2024y.
A23: =dalolatnoma!A24:E24 -> -* roʻyxatdan oʻtgan manzili/garaj manzili: SAMARQAND VILOYATI SAMARQAND SHAHAR BOG'ISARIY MAHALLASI SPITAMENSHOX KO'CHASI 252 UY
A24: =dalolatnoma!A25:E25 -> -* davlat raqami: 30O259OA
A27: «CLEVER MIKROMOLIYA TASHKILOTI» MChJ ijrochi direktori | D27: N. Abduraximov

Sheet bayonnoma
A1: =""&malumot!B155&" mikromoliya tashkiloti Kredit qo‘mitasining yig‘ilishi" -> «CLEVER MIKROMOLIYA TASHKILOTI» MChJ mikromoliya tashkiloti Kredit qo‘mitasining yig‘ilishi
A2: =""&H7&" protokolidan ko'chirma" -> №745-SM protokolidan ko'chirma
A3: Toshkent shahri | E3: =malumot!B68 -> 10 aprel 2025 y.
B4: KUN TARTIBI:
A5: =" "&H8&"."&malumot!B5&" ga "&malumot!B65&" berish masalasini ko‘rib chiqish to‘g‘risida." -> 1.DJURAKULOVA SANAM ASHUROVNA ga mikroqarz berish masalasini ko‘rib chiqish to‘g‘risida.
A7: =" "&H9&" masala yuzasidan: «Clever Mikromoliya Tashkiloti» MChJ mikromoliya tashkiloti kredit bo‘yicha menejeri "&malumot!B5&"ga "&FIXED(malumot!B75)&" ("&malumot!B76&") so‘m miqdorida, muddati "&malumot!B81&" ("&malumot!B82&") oyga va yillik 60 (Oltmish) foiz miqdorida "&malumot!B65&" berich bo‘yicha "&malumot!B5&"ning kredit arizasi va "&malumot!B155&"ning xulosasi bilan ishtirokchilarni tanishtirdi." -> Birinchi masala yuzasidan: «Clever Mikromoliya Tashkiloti» MChJ mikromoliya tashkiloti kredit bo‘yicha menejeri DJURAKULOVA SANAM ASHUROVNAga 40 000 000,00 (qirq million so'm) so‘m miqdorida, muddati 24 (Yigirma to'rt ) oyga va yillik 60 (Oltmish) foiz miqdorida mikroqarz berich bo‘yicha DJURAKULOVA SANAM ASHUROVNAning kredit arizasi va «CLEVER MIKROMOLIYA TASHKILOTI» MChJning xulosasi bilan ishtirokchilarni tanishtirdi. | G7: Protokol raqami | H7: =malumot!B1 -> №745-SM
G8: Savol raqami | H8: 1 | I8: 1 | J8: 2 | K8: 3 | L8: 4 | M8: 5 | N8: 6 | O8: 7 | P8: 8 | Q8: 9 | R8: 10 | S8: 11 | T8: 12 | U8: 13 | V8: 14 | W8: 15 | X8: 16 | Y8: 17 | Z8: 18 | AA8: 19 | AB8: 20 | AC8: 21 | AD8: 22 | AE8: 23 | AF8: 24 | AG8: 25
G9: Savol raqami qol bilan | H9: =IF(H8=I8,I9,IF(H8=J8,J9,IF(H8=K8,K9,IF(H8=L8,L9,IF(H8=M8,M9,IF(H8=N8,N9,IF(H8=O8,O9,IF(H8=P8,P9,IF(H8=Q8,Q9,IF(H8=R8,R9,IF(H8=S8,S9,IF(H8=T8,T9,IF(H8=U8,U9,IF(H8=V8,V9,IF(H8=W8,W9,IF(H8=X8,X9,IF(H8=Y8,Y9,IF(H8=Z8,Z9,IF(H8=AA8,AA9,IF(H8=AB8,AB9,IF(H8=AC8,AC9,IF(H8=AD8,AD9,IF(H8=AE8,AE9,IF(H8=AF8,AF9,IF(H8=AG8,AG9))))))))))))))))))))))))) -> Birinchi | I9: Birinchi | J9: Ikkinchi | K9: Uchinchi | L9: To'rtinchi | M9: Beshinchi | N9: O'ltinchi | O9: Yettinchi | P9: Sakkizinchi | Q9: Tuqqizinchi | R9: O'ninchi | S9: O'n birinchi | T9: O'n ikkinchi | U9: O'n uchinchi | V9: O'n to'rtinchi | W9: O'n beshinchi | X9: O'n oltinchi | Y9: O'n yettinchi | Z9: O'n sakkizinchi | AA9: O'n tuqqizinchi | AB9: Yigirmanchi | AC9: Yigirma birinchi | AD9: Yigizma ikkinchi | AE9: Yigirma uchinchi | AF9: Yigirma to'rtinchi | AG9: Yigirma beshinchi
A14: =""&malumot!C64&" ta’minoti:" -> Mikroqarz ta’minoti:
A16: =xulosa!A18:E18 -> Egalik huquqi DJURAKULOVA S.A.ga tegishli bo'lgan garovga olingan avtomobil markasi LACETTI, rangi - QORA CHERNIY, ishlab chiqarilgan yili - 2011, davlat raqam belgisi 30O259OA, kuzov turi - YENGIL SEDAN, kuzov raqami XWB5M31BDBA256320 TASH KUR GENTRA, dvigatel raqami 2132251, shassi raqami - RAKAMSIZ
C17: masala yuzasidan berilgan ma’lumotlarni muhokama qilib, Kredit qo‘mitasi a’zolariga taqdim etilgan zarur hujjatlarni o‘rganib, majlisda ishtirok etgan Kredit qo‘mitasi a’zolarining taklif va mulohazalarini inobatga olgan holda | D17: =""&malumot!B155&" kredit qo‘mitasi" -> «CLEVER MIKROMOLIYA TASHKILOTI» MChJ kredit qo‘mitasi | E17: =CONCATENATE(C17,D17) -> masala yuzasidan berilgan ma’lumotlarni muhokama qilib, Kredit qo‘mitasi a’zolariga taqdim etilgan zarur hujjatlarni o‘rganib, majlisda ishtirok etgan Kredit qo‘mitasi a’zolarining taklif va mulohazalarini inobatga olgan holda «CLEVER MIKROMOLIYA TASHKILOTI» MChJ kredit qo‘mitasi
A18: =CONCATENATE(H9,E17) -> Birinchi masala yuzasidan berilgan ma’lumotlarni muhokama qilib, Kredit qo‘mitasi a’zolariga taqdim etilgan zarur hujjatlarni o‘rganib, majlisda ishtirok etgan Kredit qo‘mitasi a’zolarining taklif va mulohazalarini inobatga olgan holda «CLEVER MIKROMOLIYA TASHKILOTI» MChJ kredit qo‘mitasi
A19: QAROR QILADI:
A20: =" "&malumot!B5&"ga quyidagi shartlarda "&malumot!B65&" berish masalasi ma’qullansin:" -> DJURAKULOVA SANAM ASHUROVNAga quyidagi shartlarda mikroqarz berish masalasi ma’qullansin:
A21: ="1. "&malumot!C64&" summasi: "&FIXED(malumot!B75)&" ("&malumot!B76&") so'm." -> 1. Mikroqarz summasi: 40 000 000,00 (qirq million so'm) so'm.
A22: ="2. "&malumot!C64&" muddati: "&malumot!B81&" ("&malumot!B82&") oy " -> 2. Mikroqarz muddati: 24 (Yigirma to'rt ) oy
A23: ="3. "&malumot!C64&"dan foydalanganlik uchun foiz stavkasi:yillik "&malumot!B85&"% ("&malumot!B86&") foiz." -> 3. Mikroqarzdan foydalanganlik uchun foiz stavkasi:yillik 55% (Ellik besh ) foiz.
A24: ="4. "&malumot!C64&" bo‘yicha asosiy qarz va foizlarni to‘lash:" -> 4. Mikroqarz bo‘yicha asosiy qarz va foizlarni to‘lash:
A25: =kredit_ariza!A19:D19 -> - mikroqarz shartnomasi bo'yicha har oy differensial to'lovlari amalga oshiriladi
A26: ="5. "&malumot!C64&" bo‘yicha garov "&xulosa!A29:E29&"" -> 5. Mikroqarz bo‘yicha garov - DJURAKULOVA S.A. ga mulk huquqi asosida tegishli avtotransport vositasi LACETTI , quyidagi tafsilotlarga muvofiq:
A27: =dalolatnoma!A29 -> Nomi | B27: =dalolatnoma!B29 -> Kuzov turi va kuzov raqami* | C27: =dalolatnoma!C29 -> Dvigatel va shassi raqami* | D27: =dalolatnoma!D29 -> Ishlab chiqarilgan yili va rangi* | E27: =dalolatnoma!E29 -> Kelishilgan garov qiymati, so'm
A28: =dalolatnoma!A30 -> LACETTI | B28: =dalolatnoma!B30 -> kuzov turi - YENGIL SEDAN, kuzov raqami XWB5M31BDBA256320 TASH KUR GENTRA | C28: =dalolatnoma!C30 -> dvigatel raqami 2132251, shassi raqami - RAKAMSIZ | D28: =dalolatnoma!D30 -> rangi - QORA CHERNIY, ishlab chiqarilgan yili - 2011 | E28: =dalolatnoma!E30 -> 56 000 000,00 (ellik olti million so'm)
A29: =dalolatnoma!A22:E22 -> -* avtotransport egasi: DJURAKULOVA S.A.
A30: =dalolatnoma!A23:E23 -> -* texnik pasport: AAG 4271140 05.07.2024y.
A31: =dalolatnoma!A24:E24 -> -* roʻyxatdan oʻtgan manzili/garaj manzili: SAMARQAND VILOYATI SAMARQAND SHAHAR BOG'ISARIY MAHALLASI SPITAMENSHOX KO'CHASI 252 UY
A32: =dalolatnoma!A25:E25 -> -* davlat raqami: 30O259OA
A34: ="6. Boshqa shartlar – "&IF(malumot!B111=malumot!B112,"avtotransport vositasi",IF(malumot!B111=malumot!C112,"ko'chmas mulk",0))&" shaklida garov ta'minlangandan keyin "&malumot!B65&" berish." -> 6. Boshqa shartlar – 0 shaklida garov ta'minlangandan keyin mikroqarz berish.
A39: Qaror bir ovozdan qabul qilindi.
A41: =malumot!B155&" ijrochi direktori" -> «CLEVER MIKROMOLIYA TASHKILOTI» MChJ ijrochi direktori | D41: N. Abduraximov
A45: =malumot!A167 -> Kreditlash bo’limi boshlig’i | D45: =malumot!B167 -> B. Mominov
A49: =malumot!A168 -> Monitoring bo’limi boshlig’i | D49: =malumot!B168 -> J.Karimov

Sheet График дифференц
E1: Приложение №1
F2: ="к договору микрозайма "&malumot!B74&"" -> к договору микрозайма 10 aprel 2025 y.dan №745-SM
A4: График погашения
L5: =malumot!B81 -> 24
A6: № | B6: Дата погашения | C6: Остаток основного долга | D6: Сумма погашения, сум
D7: основного долга | E7: процентов* | F7: всего*
A8: 1 | B8: =malumot!B79 -> 45792 | C8: =malumot!B75 -> 40000000 | D8: =IF(IF(C8=0,L8,IF(C8>1,I8))="",0,(IF(C8=0,L8,IF(C8>1,I8)))) -> 1666666.7 | E8: =IF(C8=0,N6,IF(C8>1,L8)) -> 2109589 | F8: =IF(C8=0,O6,IF(C8>1,M8)) -> 3776255.6 | G8: =B8-malumot!B67 -> 35 | H8: =DATE(YEAR(B8),12,31)-DATE(YEAR(B8),1,1)+1 -> 365 | I8: =IF(malumot!B83=0,ROUND(C8/L5,2),"") -> 1666666.7 | L8: =ROUND(C8*malumot!$B$84/H8,2)*G8 -> 2109589 | M8: =D8+E8 -> 3776255.6 | O8: =TEXT(B8,"ддд") -> Чт | P8: =IF(O8=$U$8,2,IF(O8=$V$8,1,0)) -> 0 | Q8: =DAY(malumot!$B$78)+P8 -> 15 | S8: Чт | T8: Пт | U8: Сб | V8: Вс
A9: 2 | B9: =IF(A9<=malumot!$B$81,DATE(YEAR(R9),MONTH(R9),DAY(IF(A9=malumot!$B$81,malumot!$B$67,IF(A9<malumot!$B$81,(Q9),IF(A9>malumot!$B$81,$H$56,0)))))) -> 45824 | C9: =C8-D8 -> 38333333 | D9: =IF(C9=0,L9,IF(C9>1,I9)) -> 1666666.7 | E9: =IF(C9=0,N8,IF(C9>1,L9)) -> 1848401.9 | F9: =IF(C9=0,N8,IF(C9>1,M9)) -> 3515068.6 | G9: =B9-B8 -> 32 | H9: =DATE(YEAR(B9),12,31)-DATE(YEAR(B9),1,1)+1 -> 365 | I9: =IF(I8="",ROUND(C8/(L5-1),2),I8) -> 1666666.7 | L9: =ROUND(C9*malumot!$B$84/H9,2)*G9 -> 1848401.9 | M9: =D9+E9 -> 3515068.6 | O9: =TEXT(R9,"ддд") -> Вс | P9: =IF(O9=$U$8,2,IF(O9=$V$8,1,0)) -> 1 | Q9: =DAY(malumot!$B$78)+P9 -> 16 | R9: =IF(A9<=malumot!$B$81,DATE(YEAR($B$8),MONTH($B$8)+A8,DAY(malumot!$B$78)),0) -> 45823
A10: 3 | B10: =IF(A10<=malumot!$B$81,DATE(YEAR(R10),MONTH(R10),DAY(IF(A10=malumot!$B$81,malumot!$B$67,IF(A10<malumot!$B$81,(Q10),IF(A10>malumot!$B$81,$H$56,0)))))) -> 45853 | C10: =C9-D9 -> 36666667 | D10: =IF(C10=0,L10,IF(C10>1,I10)) -> 1666666.7 | E10: =IF(C10=0,N9,IF(C10>1,L10)) -> 1602283.1 | F10: =IF(C10=0,N9,IF(C10>1,M10)) -> 3268949.7 | G10: =B10-B9 -> 29 | H10: =DATE(YEAR(B10),12,31)-DATE(YEAR(B10),1,1)+1 -> 365 | I10: =I9 -> 1666666.7 | L10: =ROUND(C10*malumot!$B$84/H10,2)*G10 -> 1602283.1 | M10: =D10+E10 -> 3268949.7 | O10: =TEXT(R10,"ддд") -> Вт | P10: =IF(O10=$U$8,2,IF(O10=$V$8,1,0)) -> 0 | Q10: =DAY(malumot!$B$78)+P10 -> 15 | R10: =IF(A10<=malumot!$B$81,DATE(YEAR($B$8),MONTH($B$8)+A9,DAY(malumot!$B$78)),0) -> 45853
A11: 4 | B11: =IF(A11<=malumot!$B$81,DATE(YEAR(R11),MONTH(R11),DAY(IF(A11=malumot!$B$81,malumot!$B$67,IF(A11<malumot!$B$81,(Q11),IF(A11>malumot!$B$81,$H$56,0)))))) -> 45884 | C11: =C10-D10 -> 35000000 | D11: =IF(C11=0,L11,IF(C11>1,I11)) -> 1666666.7 | E11: =IF(C11=0,N10,IF(C11>1,L11)) -> 1634931.6 | F11: =IF(C11=0,N10,IF(C11>1,M11)) -> 3301598.3 | G11: =B11-B10 -> 31 | H11: =DATE(YEAR(B11),12,31)-DATE(YEAR(B11),1,1)+1 -> 365 | I11: =I10 -> 1666666.7 | L11: =ROUND(C11*malumot!$B$84/H11,2)*G11 -> 1634931.6 | M11: =D11+E11 -> 3301598.3 | O11: =TEXT(R11,"ддд") -> Пт | P11: =IF(O11=$U$8,2,IF(O11=$V$8,1,0)) -> 0 | Q11: =DAY(malumot!$B$78)+P11 -> 15 | R11: =IF(A11<=malumot!$B$81,DATE(YEAR($B$8),MONTH($B$8)+A10,DAY(malumot!$B$78)),0) -> 45884
A12: 5 | B12: =IF(A12<=malumot!$B$81,DATE(YEAR(R12),MONTH(R12),DAY(IF(A12=malumot!$B$81,malumot!$B$67,IF(A12<malumot!$B$81,(Q12),IF(A12>malumot!$B$81,$H$56,0)))))) -> 45915 | C12: =C11-D11 -> 33333333 | D12: =IF(C12=0,L12,IF(C12>1,I12)) -> 1666666.7 | E12: =IF(C12=0,N11,IF(C12>1,L12)) -> 1557077.6 | F12: =IF(C12=0,N11,IF(C12>1,M12)) -> 3223744.3 | G12: =B12-B11 -> 31 | H12: =DATE(YEAR(B12),12,31)-DATE(YEAR(B12),1,1)+1 -> 365 | I12: =I11 -> 1666666.7 | J12: =malumot!B75 -> 40000000 | L12: =ROUND(C12*malumot!$B$84/H12,2)*G12 -> 1557077.6 | M12: =D12+E12 -> 3223744.3 | O12: =TEXT(R12,"ддд") -> Пн | P12: =IF(O12=$U$8,2,IF(O12=$V$8,1,0)) -> 0 | Q12: =DAY(malumot!$B$78)+P12 -> 15 | R12: =IF(A12<=malumot!$B$81,DATE(YEAR($B$8),MONTH($B$8)+A11,DAY(malumot!$B$78)),0) -> 45915
A13: 6 | B13: =IF(A13<=malumot!$B$81,DATE(YEAR(R13),MONTH(R13),DAY(IF(A13=malumot!$B$81,malumot!$B$67,IF(A13<malumot!$B$81,(Q13),IF(A13>malumot!$B$81,$H$56,0)))))) -> 45945 | C13: =C12-D12 -> 31666667 | D13: =IF(C13=0,L13,IF(C13>1,I13)) -> 1666666.7 | E13: =IF(C13=0,N12,IF(C13>1,L13)) -> 1431506.7 | F13: =IF(C13=0,N12,IF(C13>1,M13)) -> 3098173.4 | G13: =B13-B12 -> 30 | H13: =DATE(YEAR(B13),12,31)-DATE(YEAR(B13),1,1)+1 -> 365 | I13: =IF(L5=H1,K13,IF(L5>H1,I12)) -> 1666666.7 | J13: =SUM($I$8:I12) -> 8333333.3 | K13: =$J$12-J13 -> 31666667 | L13: =ROUND(C13*malumot!$B$84/H13,2)*G13 -> 1431506.7 | M13: =D13+E13 -> 3098173.4 | O13: =TEXT(R13,"ддд") -> Ср | P13: =IF(O13=$U$8,2,IF(O13=$V$8,1,0)) -> 0 | Q13: =DAY(malumot!$B$78)+P13 -> 15 | R13: =IF(A13<=malumot!$B$81,DATE(YEAR($B$8),MONTH($B$8)+A12,DAY(malumot!$B$78)),0) -> 45945
A14: 7 | B14: =IF(A14<=malumot!$B$81,DATE(YEAR(R14),MONTH(R14),DAY(IF(A14=malumot!$B$81,malumot!$B$67,IF(A14<malumot!$B$81,(Q14),IF(A14>malumot!$B$81,$H$56,0)))))) -> 45978 | C14: =C13-D13 -> 30000000 | D14: =IF(C14=0,L14,IF(C14>1,I14)) -> 1666666.7 | E14: =IF(C14=0,N13,IF(C14>1,L14)) -> 1491780.8 | F14: =IF(C14=0,N13,IF(C14>1,M14)) -> 3158447.5 | G14: =B14-B13 -> 33 | H14: =DATE(YEAR(B14),12,31)-DATE(YEAR(B14),1,1)+1 -> 365 | I14: =IF($L$5=A14,K14,IF($L$5>A14,I13)) -> 1666666.7 | J14: =SUM($I$8:I13) -> 10000000 | K14: =$J$12-J14 -> 30000000 | L14: =ROUND(C14*malumot!$B$84/H14,2)*G14 -> 1491780.8 | M14: =D14+E14 -> 3158447.5 | O14: =TEXT(R14,"ддд") -> Сб | P14: =IF(O14=$U$8,2,IF(O14=$V$8,1,0)) -> 2 | Q14: =DAY(malumot!$B$78)+P14 -> 17 | R14: =IF(A14<=malumot!$B$81,DATE(YEAR($B$8),MONTH($B$8)+A13,DAY(malumot!$B$78)),0) -> 45976
A15: 8 | B15: =IF(A15<=malumot!$B$81,DATE(YEAR(R15),MONTH(R15),DAY(IF(A15=malumot!$B$81,malumot!$B$67,IF(A15<malumot!$B$81,(Q15),IF(A15>malumot!$B$81,$H$56,0)))))) -> 46006 | C15: =C14-D14 -> 28333333 | D15: =IF(C15=0,L15,IF(C15>1,I15)) -> 1666666.7 | E15: =IF(C15=0,N14,IF(C15>1,L15)) -> 1195433.7 | F15: =IF(C15=0,N14,IF(C15>1,M15)) -> 2862100.3 | G15: =B15-B14 -> 28 | H15: =DATE(YEAR(B15),12,31)-DATE(YEAR(B15),1,1)+1 -> 365 | I15: =IF($L$5=A15,K15,IF($L$5>A15,I14)) -> 1666666.7 | J15: =SUM($I$8:I14) -> 11666667 | K15: =$J$12-J15 -> 28333333 | L15: =ROUND(C15*malumot!$B$84/H15,2)*G15 -> 1195433.7 | M15: =D15+E15 -> 2862100.3 | O15: =TEXT(R15,"ддд") -> Пн | P15: =IF(O15=$U$8,2,IF(O15=$V$8,1,0)) -> 0 | Q15: =DAY(malumot!$B$78)+P15 -> 15 | R15: =IF(A15<=malumot!$B$81,DATE(YEAR($B$8),MONTH($B$8)+A14,DAY(malumot!$B$78)),0) -> 46006
A16: 9 | B16: =IF(A16<=malumot!$B$81,DATE(YEAR(R16),MONTH(R16),DAY(IF(A16=malumot!$B$81,malumot!$B$67,IF(A16<malumot!$B$81,(Q16),IF(A16>malumot!$B$81,$H$56,0)))))) -> 46037 | C16: =C15-D15 -> 26666667 | D16: =IF(C16=0,L16,IF(C16>1,I16)) -> 1666666.7 | E16: =IF(C16=0,N15,IF(C16>1,L16)) -> 1245662.2 | F16: =IF(C16=0,N15,IF(C16>1,M16)) -> 2912328.8 | G16: =B16-B15 -> 31 | H16: =DATE(YEAR(B16),12,31)-DATE(YEAR(B16),1,1)+1 -> 365 | I16: =IF($L$5=A16,K16,IF($L$5>A16,I15)) -> 1666666.7 | J16: =SUM($I$8:I15) -> 13333333 | K16: =$J$12-J16 -> 26666667 | L16: =ROUND(C16*malumot!$B$84/H16,2)*G16 -> 1245662.2 | M16: =D16+E16 -> 2912328.8 | O16: =TEXT(R16,"ддд") -> Чт | P16: =IF(O16=$U$8,2,IF(O16=$V$8,1,0)) -> 0 | Q16: =DAY(malumot!$B$78)+P16 -> 15 | R16: =IF(A16<=malumot!$B$81,DATE(YEAR($B$8),MONTH($B$8)+A15,DAY(malumot!$B$78)),0) -> 46037
A17: 10 | B17: =IF(A17<=malumot!$B$81,DATE(YEAR(R17),MONTH(R17),DAY(IF(A17=malumot!$B$81,malumot!$B$67,IF(A17<malumot!$B$81,(Q17),IF(A17>malumot!$B$81,$H$56,0)))))) -> 46069 | C17: =C16-D16 -> 25000000 | D17: =IF(C17=0,L17,IF(C17>1,I17)) -> 1666666.7 | E17: =IF(C17=0,N16,IF(C17>1,L17)) -> 1205479.4 | F17: =IF(C17=0,N16,IF(C17>1,M17)) -> 2872146 | G17: =B17-B16 -> 32 | H17: =DATE(YEAR(B17),12,31)-DATE(YEAR(B17),1,1)+1 -> 365 | I17: =IF($L$5=A17,K17,IF($L$5>A17,I16)) -> 1666666.7 | J17: =SUM($I$8:I16) -> 15000000 | K17: =$J$12-J17 -> 25000000 | L17: =ROUND(C17*malumot!$B$84/H17,2)*G17 -> 1205479.4 | M17: =D17+E17 -> 2872146 | O17: =TEXT(R17,"ддд") -> Вс | P17: =IF(O17=$U$8,2,IF(O17=$V$8,1,0)) -> 1 | Q17: =DAY(malumot!$B$78)+P17 -> 16 | R17: =IF(A17<=malumot!$B$81,DATE(YEAR($B$8),MONTH($B$8)+A16,DAY(malumot!$B$78)),0) -> 46068
A18: 11 | B18: =IF(A18<=malumot!$B$81,DATE(YEAR(R18),MONTH(R18),DAY(IF(A18=malumot!$B$81,malumot!$B$67,IF(A18<malumot!$B$81,(Q18),IF(A18>malumot!$B$81,$H$56,0)))))) -> 46097 | C18: =C17-D17 -> 23333333 | D18: =IF(C18=0,L18,IF(C18>1,I18)) -> 1666666.7 | E18: =IF(C18=0,N17,IF(C18>1,L18)) -> 984474.96 | F18: =IF(C18=0,N17,IF(C18>1,M18)) -> 2651141.6 | G18: =B18-B17 -> 28 | H18: =DATE(YEAR(B18),12,31)-DATE(YEAR(B18),1,1)+1 -> 365 | I18: =IF($L$5=A18,K18,IF($L$5>A18,I17)) -> 1666666.7 | J18: =SUM($I$8:I17) -> 16666667 | K18: =$J$12-J18 -> 23333333 | L18: =ROUND(C18*malumot!$B$84/H18,2)*G18 -> 984474.96 | M18: =D18+E18 -> 2651141.6 | O18: =TEXT(R18,"ддд") -> Вс | P18: =IF(O18=$U$8,2,IF(O18=$V$8,1,0)) -> 1 | Q18: =DAY(malumot!$B$78)+P18 -> 16 | R18: =IF(A18<=malumot!$B$81,DATE(YEAR($B$8),MONTH($B$8)+A17,DAY(malumot!$B$78)),0) -> 46096
A19: 12 | B19: =IF(A19<=malumot!$B$81,DATE(YEAR(R19),MONTH(R19),DAY(IF(A19=malumot!$B$81,malumot!$B$67,IF(A19<malumot!$B$81,(Q19),IF(A19>malumot!$B$81,$H$56,0)))))) -> 46127 | C19: =C18-D18 -> 21666667 | D19: =IF(C19=0,L19,IF(C19>1,I19)) -> 1666666.7 | E19: =IF(C19=0,N18,IF(C19>1,L19)) -> 979452 | F19: =IF(C19=0,N18,IF(C19>1,M19)) -> 2646118.7 | G19: =B19-B18 -> 30 | H19: =DATE(YEAR(B19),12,31)-DATE(YEAR(B19),1,1)+1 -> 365 | I19: =IF($L$5=A19,K19,IF($L$5>A19,I18)) -> 1666666.7 | J19: =SUM($I$8:I18) -> 18333333 | K19: =$J$12-J19 -> 21666667 | L19: =ROUND(C19*malumot!$B$84/H19,2)*G19 -> 979452 | M19: =D19+E19 -> 2646118.7 | O19: =TEXT(R19,"ддд") -> Ср | P19: =IF(O19=$U$8,2,IF(O19=$V$8,1,0)) -> 0 | Q19: =DAY(malumot!$B$78)+P19 -> 15 | R19: =IF(A19<=malumot!$B$81,DATE(YEAR($B$8),MONTH($B$8)+A18,DAY(malumot!$B$78)),0) -> 46127
A20: 13 | B20: =IF(A20<=malumot!$B$81,DATE(YEAR(R20),MONTH(R20),DAY(IF(A20=malumot!$B$81,malumot!$B$67,IF(A20<malumot!$B$81,(Q20),IF(A20>malumot!$B$81,$H$56,0)))))) -> 46157 | C20: =C19-D19 -> 20000000 | D20: =IF(C20=0,L20,IF(C20>1,I20)) -> 1666666.7 | E20: =IF(C20=0,N19,IF(C20>1,L20)) -> 904109.7 | F20: =IF(C20=0,N19,IF(C20>1,M20)) -> 2570776.4 | G20: =B20-B19 -> 30 | H20: =DATE(YEAR(B20),12,31)-DATE(YEAR(B20),1,1)+1 -> 365 | I20: =IF($L$5=A20,K20,IF($L$5>A20,I19)) -> 1666666.7 | J20: =SUM($I$8:I19) -> 20000000 | K20: =$J$12-J20 -> 20000000 | L20: =ROUND(C20*malumot!$B$84/H20,2)*G20 -> 904109.7 | M20: =D20+E20 -> 2570776.4 | O20: =TEXT(R20,"ддд") -> Пт | P20: =IF(O20=$U$8,2,IF(O20=$V$8,1,0)) -> 0 | Q20: =DAY(malumot!$B$78)+P20 -> 15 | R20: =IF(A20<=malumot!$B$81,DATE(YEAR($B$8),MONTH($B$8)+A19,DAY(malumot!$B$78)),0) -> 46157
A21: 14 | B21: =IF(A21<=malumot!$B$81,DATE(YEAR(R21),MONTH(R21),DAY(IF(A21=malumot!$B$81,malumot!$B$67,IF(A21<malumot!$B$81,(Q21),IF(A21>malumot!$B$81,$H$56,0)))))) -> 46188 | C21: =C20-D20 -> 18333333 | D21: =IF(C21=0,L21,IF(C21>1,I21)) -> 1666666.7 | E21: =IF(C21=0,N20,IF(C21>1,L21)) -> 856392.67 | F21: =IF(C21=0,N20,IF(C21>1,M21)) -> 2523059.3 | G21: =B21-B20 -> 31 | H21: =DATE(YEAR(B21),12,31)-DATE(YEAR(B21),1,1)+1 -> 365 | I21: =IF($L$5=A21,K21,IF($L$5>A21,I20)) -> 1666666.7 | J21: =SUM($I$8:I20) -> 21666667 | K21: =$J$12-J21 -> 18333333 | L21: =ROUND(C21*malumot!$B$84/H21,2)*G21 -> 856392.67 | M21: =D21+E21 -> 2523059.3 | O21: =TEXT(R21,"ддд") -> Пн | P21: =IF(O21=$U$8,2,IF(O21=$V$8,1,0)) -> 0 | Q21: =DAY(malumot!$B$78)+P21 -> 15 | R21: =IF(A21<=malumot!$B$81,DATE(YEAR($B$8),MONTH($B$8)+A20,DAY(malumot!$B$78)),0) -> 46188
A22: 15 | B22: =IF(A22<=malumot!$B$81,DATE(YEAR(R22),MONTH(R22),DAY(IF(A22=malumot!$B$81,malumot!$B$67,IF(A22<malumot!$B$81,(Q22),IF(A22>malumot!$B$81,$H$56,0)))))) -> 46218 | C22: =C21-D21 -> 16666667 | D22: =IF(C22=0,L22,IF(C22>1,I22)) -> 1666666.7 | E22: =IF(C22=0,N21,IF(C22>1,L22)) -> 753424.8 | F22: =IF(C22=0,N21,IF(C22>1,M22)) -> 2420091.5 | G22: =B22-B21 -> 30 | H22: =DATE(YEAR(B22),12,31)-DATE(YEAR(B22),1,1)+1 -> 365 | I22: =IF($L$5=A22,K22,IF($L$5>A22,I21)) -> 1666666.7 | J22: =SUM($I$8:I21) -> 23333333 | K22: =$J$12-J22 -> 16666667 | L22: =ROUND(C22*malumot!$B$84/H22,2)*G22 -> 753424.8 | M22: =D22+E22 -> 2420091.5 | O22: =TEXT(R22,"ддд") -> Ср | P22: =IF(O22=$U$8,2,IF(O22=$V$8,1,0)) -> 0 | Q22: =DAY(malumot!$B$78)+P22 -> 15 | R22: =IF(A22<=malumot!$B$81,DATE(YEAR($B$8),MONTH($B$8)+A21,DAY(malumot!$B$78)),0) -> 46218
A23: 16 | B23: =IF(A23<=malumot!$B$81,DATE(YEAR(R23),MONTH(R23),DAY(IF(A23=malumot!$B$81,malumot!$B$67,IF(A23<malumot!$B$81,(Q23),IF(A23>malumot!$B$81,$H$56,0)))))) -> 46251 | C23: =C22-D22 -> 15000000 | D23: =IF(C23=0,L23,IF(C23>1,I23)) -> 1666666.7 | E23: =IF(C23=0,N22,IF(C23>1,L23)) -> 745890.42 | F23: =IF(C23=0,N22,IF(C23>1,M23)) -> 2412557.1 | G23: =B23-B22 -> 33 | H23: =DATE(YEAR(B23),12,31)-DATE(YEAR(B23),1,1)+1 -> 365 | I23: =IF($L$5=A23,K23,IF($L$5>A23,I22)) -> 1666666.7 | J23: =SUM($I$8:I22) -> 25000000 | K23: =$J$12-J23 -> 15000000 | L23: =ROUND(C23*malumot!$B$84/H23,2)*G23 -> 745890.42 | M23: =D23+E23 -> 2412557.1 | O23: =TEXT(R23,"ддд") -> Сб | P23: =IF(O23=$U$8,2,IF(O23=$V$8,1,0)) -> 2 | Q23: =DAY(malumot!$B$78)+P23 -> 17 | R23: =IF(A23<=malumot!$B$81,DATE(YEAR($B$8),MONTH($B$8)+A22,DAY(malumot!$B$78)),0) -> 46249
A24: 17 | B24: =IF(A24<=malumot!$B$81,DATE(YEAR(R24),MONTH(R24),DAY(IF(A24=malumot!$B$81,malumot!$B$67,IF(A24<malumot!$B$81,(Q24),IF(A24>malumot!$B$81,$H$56,0)))))) -> 46280 | C24: =C23-D23 -> 13333333 | D24: =IF(C24=0,L24,IF(C24>1,I24)) -> 1666666.7 | E24: =IF(C24=0,N23,IF(C24>1,L24)) -> 582648.28 | F24: =IF(C24=0,N23,IF(C24>1,M24)) -> 2249315 | G24: =B24-B23 -> 29 | H24: =DATE(YEAR(B24),12,31)-DATE(YEAR(B24),1,1)+1 -> 365 | I24: =IF($L$5=A24,K24,IF($L$5>A24,I23)) -> 1666666.7 | J24: =SUM($I$8:I23) -> 26666667 | K24: =$J$12-J24 -> 13333333 | L24: =ROUND(C24*malumot!$B$84/H24,2)*G24 -> 582648.28 | M24: =D24+E24 -> 2249315 | O24: =TEXT(R24,"ддд") -> Вт | P24: =IF(O24=$U$8,2,IF(O24=$V$8,1,0)) -> 0 | Q24: =DAY(malumot!$B$78)+P24 -> 15 | R24: =IF(A24<=malumot!$B$81,DATE(YEAR($B$8),MONTH($B$8)+A23,DAY(malumot!$B$78)),0) -> 46280
A25: 18 | B25: =IF(A25<=malumot!$B$81,DATE(YEAR(R25),MONTH(R25),DAY(IF(A25=malumot!$B$81,malumot!$B$67,IF(A25<malumot!$B$81,(Q25),IF(A25>malumot!$B$81,$H$56,0)))))) -> 46310 | C25: =C24-D24 -> 11666667 | D25: =IF(C25=0,L25,IF(C25>1,I25)) -> 1666666.7 | E25: =IF(C25=0,N24,IF(C25>1,L25)) -> 527397.3 | F25: =IF(C25=0,N24,IF(C25>1,M25)) -> 2194064 | G25: =B25-B24 -> 30 | H25: =DATE(YEAR(B25),12,31)-DATE(YEAR(B25),1,1)+1 -> 365 | I25: =IF($L$5=A25,K25,IF($L$5>A25,I24)) -> 1666666.7 | J25: =SUM($I$8:I24) -> 28333333 | K25: =$J$12-J25 -> 11666667 | L25: =ROUND(C25*malumot!$B$84/H25,2)*G25 -> 527397.3 | M25: =D25+E25 -> 2194064 | O25: =TEXT(R25,"ддд") -> Чт | P25: =IF(O25=$U$8,2,IF(O25=$V$8,1,0)) -> 0 | Q25: =DAY(malumot!$B$78)+P25 -> 15 | R25: =IF(A25<=malumot!$B$81,DATE(YEAR($B$8),MONTH($B$8)+A24,DAY(malumot!$B$78)),0) -> 46310
... A31: 24 | B31: =IF(A31<=malumot!$B$81,DATE(YEAR(R31),MONTH(R31),DAY(IF(A31=malumot!$B$81,malumot!$B$67,IF(A31<malumot!$B$81,(Q31),IF(A31>malumot!$B$81,$H$56,0)))))) -> 46487 | C31: =C30-D30 -> 1666666.6 | D31: =IF(C31=0,L31,IF(C31>1,I31)) -> 1666666.6 | E31: =IF(C31=0,N30,IF(C31>1,L31)) -> 65296.92 | F31: =IF(C31=0,N30,IF(C31>1,M31)) -> 1731963.5 | G31: =B31-B30 -> 26 | H31: =DATE(YEAR(B31),12,31)-DATE(YEAR(B31),1,1)+1 -> 365 | I31: =IF($L$5=A31,K31,IF($L$5>A31,I30)) -> 1666666.6 | J31: =SUM($I$8:I30) -> 38333333 | K31: =$J$12-J31 -> 1666666.6 | L31: =ROUND(C31*malumot!$B$84/H31,2)*G31 -> 65296.92 | M31: =D31+E31 -> 1731963.5 | O31: =TEXT(R31,"ддд") -> Чт | P31: =IF(O31=$U$8,2,IF(O31=$V$8,1,0)) -> 0 | Q31: =DAY(malumot!$B$78)+P31 -> 15 | R31: =IF(A31<=malumot!$B$81,DATE(YEAR($B$8),MONTH($B$8)+A30,DAY(malumot!$B$78)),0) -> 46492
A32: =1+A31 -> 25 | B32: =IF(A32<=malumot!$B$81,DATE(YEAR(R32),MONTH(R32),DAY(IF(A32=malumot!$B$81,malumot!$B$67,IF(A32<malumot!$B$81,(Q32),IF(A32>malumot!$B$81,$H$56,0)))))) -> FALSE | C32: =C31-D31 -> -3.7252903e-09 | D32: =IF(C32=0,L32,IF(C32>1,I32)) -> FALSE | E32: =IF(C32=0,N31,IF(C32>1,L32)) -> FALSE | F32: =IF(C32=0,N31,IF(C32>1,M32)) -> FALSE | G32: =B32-B31 -> -46487 | H32: =DATE(YEAR(B32),12,31)-DATE(YEAR(B32),1,1)+1 -> 366 | I32: =IF($L$5=A32,K32,IF($L$5>A32,I31)) -> FALSE | J32: =SUM($I$8:I31) -> 40000000 | K32: =$J$12-J32 -> 0 | L32: =ROUND(C32*malumot!$B$84/H32,2)*G32 -> 0 | M32: =D32+E32 -> 0 | O32: =TEXT(R32,"ддд") -> Сб | P32: =IF(O32=$U$8,2,IF(O32=$V$8,1,0)) -> 2 | Q32: =DAY(malumot!$B$78)+P32 -> 17 | R32: =IF(A32<=malumot!$B$81,DATE(YEAR($B$8),MONTH($B$8)+A31,DAY(malumot!$B$78)),0) -> 0
A33: =1+A32 -> 26 | B33: =IF(A33<=malumot!$B$81,DATE(YEAR(R33),MONTH(R33),DAY(IF(A33=malumot!$B$81,malumot!$B$67,IF(A33<malumot!$B$81,(Q33),IF(A33>malumot!$B$81,$H$56,0)))))) -> FALSE | C33: =C32-D32 -> -3.7252903e-09 | D33: =IF(C33=0,L33,IF(C33>1,I33)) -> FALSE | E33: =IF(C33=0,N32,IF(C33>1,L33)) -> FALSE | F33: =IF(C33=0,N32,IF(C33>1,M33)) -> FALSE | G33: =B33-B32 -> 0 | H33: =DATE(YEAR(B33),12,31)-DATE(YEAR(B33),1,1)+1 -> 366 | I33: =IF($L$5=A33,K33,IF($L$5>A33,I32)) -> FALSE | J33: =SUM($I$8:I32) -> 40000000 | K33: =$J$12-J33 -> 0 | L33: =ROUND(C33*malumot!$B$84/H33,2)*G33 -> 0 | M33: =D33+E33 -> 0 | O33: =TEXT(R33,"ддд") -> Сб | P33: =IF(O33=$U$8,2,IF(O33=$V$8,1,0)) -> 2 | Q33: =DAY(malumot!$B$78)+P33 -> 17 | R33: =IF(A33<=malumot!$B$81,DATE(YEAR($B$8),MONTH($B$8)+A32,DAY(malumot!$B$78)),0) -> 0
A34: =1+A33 -> 27 | B34: =IF(A34<=malumot!$B$81,DATE(YEAR(R34),MONTH(R34),DAY(IF(A34=malumot!$B$81,malumot!$B$67,IF(A34<malumot!$B$81,(Q34),IF(A34>malumot!$B$81,$H$56,0)))))) -> FALSE | C34: =C33-D33 -> -3.7252903e-09 | D34: =IF(C34=0,L34,IF(C34>1,I34)) -> FALSE | E34: =IF(C34=0,N33,IF(C34>1,L34)) -> FALSE | F34: =IF(C34=0,N33,IF(C34>1,M34)) -> FALSE | G34: =B34-B33 -> 0 | H34: =DATE(YEAR(B34),12,31)-DATE(YEAR(B34),1,1)+1 -> 366 | I34: =IF($L$5=A34,K34,IF($L$5>A34,I33)) -> FALSE | J34: =SUM($I$8:I33) -> 40000000 | K34: =$J$12-J34 -> 0 | L34: =ROUND(C34*malumot!$B$84/H34,2)*G34 -> 0 | M34: =D34+E34 -> 0 | O34: =TEXT(R34,"ддд") -> Сб | P34: =IF(O34=$U$8,2,IF(O34=$V$8,1,0)) -> 2 | Q34: =DAY(malumot!$B$78)+P34 -> 17 | R34: =IF(A34<=malumot!$B$81,DATE(YEAR($B$8),MONTH($B$8)+A33,DAY(malumot!$B$78)),0) -> 0
A35: =1+A34 -> 28 | B35: =IF(A35<=malumot!$B$81,DATE(YEAR(R35),MONTH(R35),DAY(IF(A35=malumot!$B$81,malumot!$B$67,IF(A35<malumot!$B$81,(Q35),IF(A35>malumot!$B$81,$H$56,0)))))) -> FALSE | C35: =C34-D34 -> -3.7252903e-09 | D35: =IF(C35=0,L35,IF(C35>1,I35)) -> FALSE | E35: =IF(C35=0,N34,IF(C35>1,L35)) -> FALSE | F35: =IF(C35=0,N34,IF(C35>1,M35)) -> FALSE | G35: =B35-B34 -> 0 | H35: =DATE(YEAR(B35),12,31)-DATE(YEAR(B35),1,1)+1 -> 366 | I35: =IF($L$5=A35,K35,IF($L$5>A35,I34)) -> FALSE | J35: =SUM($I$8:I34) -> 40000000 | K35: =$J$12-J35 -> 0 | L35: =ROUND(C35*malumot!$B$84/H35,2)*G35 -> 0 | M35: =D35+E35 -> 0 | O35: =TEXT(R35,"ддд") -> Сб | P35: =IF(O35=$U$8,2,IF(O35=$V$8,1,0)) -> 2 | Q35: =DAY(malumot!$B$78)+P35 -> 17 | R35: =IF(A35<=malumot!$B$81,DATE(YEAR($B$8),MONTH($B$8)+A34,DAY(malumot!$B$78)),0) -> 0
